Workbook

Sheet Portfolio
A1: Portfolio Size | B1: 5000 | C1: Maximum budget per stock | D1: 1000 | E1: Min Entry Size | F1: 300 | G1: No ETFs/Reits | H1: 5 Stocks | I1: Amount Invested | J1: =sum(H:H) -> #N/A | K1: Invested Value | L1: =sum(I:I) -> #N/A | M1: Portfolio Return | N1: =(L1-J1)/B1 -> #N/A | O1: Portfolio Cash | P1: =B1-J1 -> #N/A | Q1: =L1-J1+B1 -> #N/A | R1: Look out for Big red number in this column
A2: Master Watchlist | B2: 300 | C2: 300 | D2: 400 | E2: <=== How to spend the £1000 HL | H2: 100 | I2: 150 | J2: 250 | K2: <=== How to spend the £500
A3: Ticker | B3: Name | C3: Reason for Entry | D3: Current Price | E3: Trading 212/Freetrade entry price | F3: Average Entry Price | G3: Number of Shares | H3: Current Cost | I3: Current Value | J3: % Weight of Portfolio | K3: Current Return (%) | L3: 30 Day Trend Chart | M3: Ccy | N3: Daily Change (%) | O3: Daily Change | P3: Daily High | Q3: Daily Low | R3: Range/ yest close | S3: Price/ year low | T3: Target Entry for Averaging | U3: Target Exit | V3: Trade Alert | W3: TRADE ALERT | X3: beta | Y3: low52 | Z3: high52 | AA3: volume avg | AB3: pe | AC3: datadelay | AD3: marketcap | AE3: Closeyest
A4: SPCE | B4: =IFERROR(__xludf.DUMMYFUNCTION("GOOGLEFINANCE(A4,""name"")"),"Virgin Galactic Holdings Inc") -> Virgin Galactic Holdings Inc | D4: =IFERROR(__xludf.DUMMYFUNCTION("GOOGLEFINANCE(A4)"),2.52) -> 2.52 | F4: =IF(M4="USD",E4/1.21,E4) -> 0 | H4: =IFERROR(__xludf.DUMMYFUNCTION("if(isblank(A4)=TRUE,0,if(M4=""GBX"",F4*G4/100,IF(M4=""EUR"",F4*G4/GOOGLEFINANCE(""CURRENCY:GBPEUR""),F4*G4/GOOGLEFINANCE(""CURRENCY:GBPUSD""))))"),0.0) -> 0 | I4: =IFERROR(__xludf.DUMMYFUNCTION("if(isblank(A4)=TRUE,0,if(M4=""GBX"",D4*G4/100,IF(M4=""EUR"",D4*G4/GOOGLEFINANCE(""CURRENCY:GBPEUR""),D4*G4/GOOGLEFINANCE(""CURRENCY:GBPUSD""))))"),0.0) -> 0 | J4: =H4/$B$1 -> 0 | K4: =I4/H4-1 -> #DIV/0! | L4: =IFERROR(__xludf.DUMMYFUNCTION("SPARKLINE(GoogleFinance(A4, ""price"", TODAY()-30, TODAY()),{""color"",""blue"";""linewidth"",2}) "),"") | M4: =IFERROR(__xludf.DUMMYFUNCTION("GOOGLEFINANCE(A4,""currency"")"),"USD") -> USD | N4: =round(D4/AE4-1,4) -> -0.0156 | O4: =IFERROR(__xludf.DUMMYFUNCTION("GOOGLEFINANCE(A4,""Change"")"),-0.04) -> -0.04 | P4: =IFERROR(__xludf.DUMMYFUNCTION("GOOGLEFINANCE(A4,""High"")"),2.54) -> 2.54 | Q4: =IFERROR(__xludf.DUMMYFUNCTION("GOOGLEFINANCE(A4,""low"")"),2.46) -> 2.46 | R4: =IFERROR(__xludf.DUMMYFUNCTION("abs(P4-Q4)/GOOGLEFINANCE(A4,""closeyest"")"),0.03125000000000003) -> 0.03125 | S4: =D4/Y4-1 -> 0.1559633 | T4: 43 | W4: =IF(ISERROR(if(or(AND(Q4<=T4,T4<=P4),AND(Q4<=U4, U4<=P4)),"TRADE ALERT","")),"DATA UNAVAILABLE",if(or(AND(Q4<=T4,T4<=P4),T4>P4,AND(Q4<=U4, U4<=P4)),"TRADE ALERT"&" - Price level hit for "&A4&" currently at "&D4&" "&B4,"")) -> TRADE ALERT - Price level hit for SPCE currently at 2.52 Virgin Galactic Holdings Inc | X4: =IFERROR(__xludf.DUMMYFUNCTION("GOOGLEFINANCE($A4,X$3)"),2.21) -> 2.21 | Y4: =IFERROR(__xludf.DUMMYFUNCTION("GOOGLEFINANCE($A4,Y$3)"),2.18) -> 2.18 | Z4: =IFERROR(__xludf.DUMMYFUNCTION("GOOGLEFINANCE($A4,Z$3)"),6.64) -> 6.64 | AA4: =IFERROR(__xludf.DUMMYFUNCTION("GOOGLEFINANCE($A4,AA$3)"),"#N/A") -> #N/A | AB4: =IFERROR(__xludf.DUMMYFUNCTION("GOOGLEFINANCE($A4,AB$3)"),"#N/A") -> #N/A | AC4: =IFERROR(__xludf.DUMMYFUNCTION("GOOGLEFINANCE($A4,AC$3)"),0.0) -> 0 | AD4: =IFERROR(__xludf.DUMMYFUNCTION("GOOGLEFINANCE($A4,AD$3)"),1.8428591E8) -> 184285910 | AE4: =IFERROR(__xludf.DUMMYFUNCTION("GOOGLEFINANCE($A4,AE$3)"),2.56) -> 2.56
A5: JMIA | B5: =IFERROR(__xludf.DUMMYFUNCTION("GOOGLEFINANCE(A5,""name"")"),"Jumia Technologies AG - ADR") -> Jumia Technologies AG - ADR | D5: =IFERROR(__xludf.DUMMYFUNCTION("GOOGLEFINANCE(A5)"),9.34) -> 9.34 | F5: =IF(M5="USD",E5/1.21,E5) -> 0 | H5: =IFERROR(__xludf.DUMMYFUNCTION("if(isblank(A5)=TRUE,0,if(M5=""GBX"",F5*G5/100,IF(M5=""EUR"",F5*G5/GOOGLEFINANCE(""CURRENCY:GBPEUR""),F5*G5/GOOGLEFINANCE(""CURRENCY:GBPUSD""))))"),0.0) -> 0 | I5: =IFERROR(__xludf.DUMMYFUNCTION("if(isblank(A5)=TRUE,0,if(M5=""GBX"",D5*G5/100,IF(M5=""EUR"",D5*G5/GOOGLEFINANCE(""CURRENCY:GBPEUR""),D5*G5/GOOGLEFINANCE(""CURRENCY:GBPUSD""))))"),0.0) -> 0 | J5: =H5/$B$1 -> 0 | K5: =I5/H5-1 -> #DIV/0! | L5: =IFERROR(__xludf.DUMMYFUNCTION("SPARKLINE(GoogleFinance(A5, ""price"", TODAY()-30, TODAY()),{""color"",""blue"";""linewidth"",2}) "),"") | M5: =IFERROR(__xludf.DUMMYFUNCTION("GOOGLEFINANCE(A5,""currency"")"),"USD") -> USD | N5: =round(D5/AE5-1,4) -> 0.0021 | O5: =IFERROR(__xludf.DUMMYFUNCTION("GOOGLEFINANCE(A5,""Change"")"),0.02) -> 0.02 | P5: =IFERROR(__xludf.DUMMYFUNCTION("GOOGLEFINANCE(A5,""High"")"),9.34) -> 9.34 | Q5: =IFERROR(__xludf.DUMMYFUNCTION("GOOGLEFINANCE(A5,""low"")"),9.01) -> 9.01 | R5: =IFERROR(__xludf.DUMMYFUNCTION("abs(P5-Q5)/GOOGLEFINANCE(A5,""closeyest"")"),0.03540772532188842) -> 0.035407725 | S5: =D5/Y5-1 -> 4.8375 | T5: 39 | W5: =IF(ISERROR(if(or(AND(Q5<=T5,T5<=P5),AND(Q5<=U5, U5<=P5)),"TRADE ALERT","")),"DATA UNAVAILABLE",if(or(AND(Q5<=T5,T5<=P5),T5>P5,AND(Q5<=U5, U5<=P5)),"TRADE ALERT"&" - Price level hit for "&A5&" currently at "&D5&" "&B5,"")) -> TRADE ALERT - Price level hit for JMIA currently at 9.34 Jumia Technologies AG - ADR | X5: =IFERROR(__xludf.DUMMYFUNCTION("GOOGLEFINANCE($A5,X$3)"),2.34) -> 2.34 | Y5: =IFERROR(__xludf.DUMMYFUNCTION("GOOGLEFINANCE($A5,Y$3)"),1.6) -> 1.6 | Z5: =IFERROR(__xludf.DUMMYFUNCTION("GOOGLEFINANCE($A5,Z$3)"),14.72) -> 14.72 | AA5: =IFERROR(__xludf.DUMMYFUNCTION("GOOGLEFINANCE($A5,AA$3)"),"#N/A") -> #N/A | AB5: =IFERROR(__xludf.DUMMYFUNCTION("GOOGLEFINANCE($A5,AB$3)"),"#N/A") -> #N/A | AC5: =IFERROR(__xludf.DUMMYFUNCTION("GOOGLEFINANCE($A5,AC$3)"),0.0) -> 0 | AD5: =IFERROR(__xludf.DUMMYFUNCTION("GOOGLEFINANCE($A5,AD$3)"),1.142577914E9) -> 1142577914 | AE5: =IFERROR(__xludf.DUMMYFUNCTION("GOOGLEFINANCE($A5,AE$3)"),9.32) -> 9.32
A6: TOOP | B6: =IFERROR(__xludf.DUMMYFUNCTION("GOOGLEFINANCE(A6,""name"")"),"#N/A") -> #N/A | D6: =IFERROR(__xludf.DUMMYFUNCTION("GOOGLEFINANCE(A6)"),"#N/A") -> #N/A | F6: =IF(M6="USD",E6/1.21,E6) -> #N/A | H6: =IFERROR(__xludf.DUMMYFUNCTION("if(isblank(A6)=TRUE,0,if(M6=""GBX"",F6*G6/100,IF(M6=""EUR"",F6*G6/GOOGLEFINANCE(""CURRENCY:GBPEUR""),F6*G6/GOOGLEFINANCE(""CURRENCY:GBPUSD""))))"),"#N/A") -> #N/A | I6: =IFERROR(__xludf.DUMMYFUNCTION("if(isblank(A6)=TRUE,0,if(M6=""GBX"",D6*G6/100,IF(M6=""EUR"",D6*G6/GOOGLEFINANCE(""CURRENCY:GBPEUR""),D6*G6/GOOGLEFINANCE(""CURRENCY:GBPUSD""))))"),"#N/A") -> #N/A | J6: =H6/$B$1 -> #N/A | K6: =I6/H6-1 -> #N/A | L6: =IFERROR(__xludf.DUMMYFUNCTION("SPARKLINE(GoogleFinance(A6, ""price"", TODAY()-30, TODAY()),{""color"",""blue"";""linewidth"",2}) "),"#N/A") -> #N/A | M6: =IFERROR(__xludf.DUMMYFUNCTION("GOOGLEFINANCE(A6,""currency"")"),"#N/A") -> #N/A | N6: =round(D6/AE6-1,4) -> #N/A | O6: =IFERROR(__xludf.DUMMYFUNCTION("GOOGLEFINANCE(A6,""Change"")"),"#N/A") -> #N/A | P6: =IFERROR(__xludf.DUMMYFUNCTION("GOOGLEFINANCE(A6,""High"")"),"#N/A") -> #N/A | Q6: =IFERROR(__xludf.DUMMYFUNCTION("GOOGLEFINANCE(A6,""low"")"),"#N/A") -> #N/A | R6: =IFERROR(__xludf.DUMMYFUNCTION("abs(P6-Q6)/GOOGLEFINANCE(A6,""closeyest"")"),"#N/A") -> #N/A | S6: =D6/Y6-1 -> #N/A | T6: 1.95 | W6: =IF(ISERROR(if(or(AND(Q6<=T6,T6<=P6),AND(Q6<=U6, U6<=P6)),"TRADE ALERT","")),"DATA UNAVAILABLE",if(or(AND(Q6<=T6,T6<=P6),T6>P6,AND(Q6<=U6, U6<=P6)),"TRADE ALERT"&" - Price level hit for "&A6&" currently at "&D6&" "&B6,"")) -> DATA UNAVAILABLE | X6: =IFERROR(__xludf.DUMMYFUNCTION("GOOGLEFINANCE($A6,X$3)"),"#N/A") -> #N/A | Y6: =IFERROR(__xludf.DUMMYFUNCTION("GOOGLEFINANCE($A6,Y$3)"),"#N/A") -> #N/A | Z6: =IFERROR(__xludf.DUMMYFUNCTION("GOOGLEFINANCE($A6,Z$3)"),"#N/A") -> #N/A | AA6: =IFERROR(__xludf.DUMMYFUNCTION("GOOGLEFINANCE($A6,AA$3)"),"#N/A") -> #N/A | AB6: =IFERROR(__xludf.DUMMYFUNCTION("GOOGLEFINANCE($A6,AB$3)"),"#N/A") -> #N/A | AC6: =IFERROR(__xludf.DUMMYFUNCTION("GOOGLEFINANCE($A6,AC$3)"),"#N/A") -> #N/A | AD6: =IFERROR(__xludf.DUMMYFUNCTION("GOOGLEFINANCE($A6,AD$3)"),"#N/A") -> #N/A | AE6: =IFERROR(__xludf.DUMMYFUNCTION("GOOGLEFINANCE($A6,AE$3)"),"#N/A") -> #N/A
A7: RGB | B7: =IFERROR(__xludf.DUMMYFUNCTION("GOOGLEFINANCE(A7,""name"")"),"Russell Inv Australian Government Bond ETF") -> Russell Inv Australian Government Bond ETF | D7: =IFERROR(__xludf.DUMMYFUNCTION("GOOGLEFINANCE(A7)"),19.02) -> 19.02 | F7: =IF(M7="USD",E7/1.21,E7) | H7: =IFERROR(__xludf.DUMMYFUNCTION("if(isblank(A7)=TRUE,0,if(M7=""GBX"",F7*G7/100,IF(M7=""EUR"",F7*G7/GOOGLEFINANCE(""CURRENCY:GBPEUR""),F7*G7/GOOGLEFINANCE(""CURRENCY:GBPUSD""))))"),0.0) -> 0 | I7: =IFERROR(__xludf.DUMMYFUNCTION("if(isblank(A7)=TRUE,0,if(M7=""GBX"",D7*G7/100,IF(M7=""EUR"",D7*G7/GOOGLEFINANCE(""CURRENCY:GBPEUR""),D7*G7/GOOGLEFINANCE(""CURRENCY:GBPUSD""))))"),0.0) -> 0 | J7: =H7/$B$1 -> 0 | K7: =I7/H7-1 -> #DIV/0! | L7: =IFERROR(__xludf.DUMMYFUNCTION("SPARKLINE(GoogleFinance(A7, ""price"", TODAY()-30, TODAY()),{""color"",""blue"";""linewidth"",2}) "),"") | M7: =IFERROR(__xludf.DUMMYFUNCTION("GOOGLEFINANCE(A7,""currency"")"),"AUD") -> AUD | N7: =round(D7/AE7-1,4) -> 0.0016 | O7: =IFERROR(__xludf.DUMMYFUNCTION("GOOGLEFINANCE(A7,""Change"")"),0.03) -> 0.03 | P7: =IFERROR(__xludf.DUMMYFUNCTION("GOOGLEFINANCE(A7,""High"")"),19.02) -> 19.02 | Q7: =IFERROR(__xludf.DUMMYFUNCTION("GOOGLEFINANCE(A7,""low"")"),18.95) -> 18.95 | R7: =IFERROR(__xludf.DUMMYFUNCTION("abs(P7-Q7)/GOOGLEFINANCE(A7,""closeyest"")"),0.0036861506055819006) -> 0.0036861506 | S7: =D7/Y7-1 -> 0.017112299 | T7: 115 | W7: =IF(ISERROR(if(or(AND(Q7<=T7,T7<=P7),AND(Q7<=U7, U7<=P7)),"TRADE ALERT","")),"DATA UNAVAILABLE",if(or(AND(Q7<=T7,T7<=P7),T7>P7,AND(Q7<=U7, U7<=P7)),"TRADE ALERT"&" - Price level hit for "&A7&" currently at "&D7&" "&B7,"")) -> TRADE ALERT - Price level hit for RGB currently at 19.02 Russell Inv Australian Government Bond ETF | X7: =IFERROR(__xludf.DUMMYFUNCTION("GOOGLEFINANCE($A7,X$3)"),"#N/A") -> #N/A | Y7: =IFERROR(__xludf.DUMMYFUNCTION("GOOGLEFINANCE($A7,Y$3)"),18.7) -> 18.7 | Z7: =IFERROR(__xludf.DUMMYFUNCTION("GOOGLEFINANCE($A7,Z$3)"),20.02) -> 20.02 | AA7: =IFERROR(__xludf.DUMMYFUNCTION("GOOGLEFINANCE($A7,AA$3)"),"#N/A") -> #N/A | AB7: =IFERROR(__xludf.DUMMYFUNCTION("GOOGLEFINANCE($A7,AB$3)"),"#N/A") -> #N/A | AC7: =IFERROR(__xludf.DUMMYFUNCTION("GOOGLEFINANCE($A7,AC$3)"),20.0) -> 20 | AD7: =IFERROR(__xludf.DUMMYFUNCTION("GOOGLEFINANCE($A7,AD$3)"),"#N/A") -> #N/A | AE7: =IFERROR(__xludf.DUMMYFUNCTION("GOOGLEFINANCE($A7,AE$3)"),18.99) -> 18.99
A8: KODK | B8: =IFERROR(__xludf.DUMMYFUNCTION("GOOGLEFINANCE(A8,""name"")"),"Eastman Kodak Co") -> Eastman Kodak Co | D8: =IFERROR(__xludf.DUMMYFUNCTION("GOOGLEFINANCE(A8)"),7.73) -> 7.73 | F8: =IF(M8="USD",E8/1.21,E8) -> 0 | H8: =IFERROR(__xludf.DUMMYFUNCTION("if(isblank(A8)=TRUE,0,if(M8=""GBX"",F8*G8/100,IF(M8=""EUR"",F8*G8/GOOGLEFINANCE(""CURRENCY:GBPEUR""),F8*G8/GOOGLEFINANCE(""CURRENCY:GBPUSD""))))"),0.0) -> 0 | I8: =IFERROR(__xludf.DUMMYFUNCTION("if(isblank(A8)=TRUE,0,if(M8=""GBX"",D8*G8/100,IF(M8=""EUR"",D8*G8/GOOGLEFINANCE(""CURRENCY:GBPEUR""),D8*G8/GOOGLEFINANCE(""CURRENCY:GBPUSD""))))"),0.0) -> 0 | J8: =H8/$B$1 -> 0 | K8: =I8/H8-1 -> #DIV/0! | L8: =IFERROR(__xludf.DUMMYFUNCTION("SPARKLINE(GoogleFinance(A8, ""price"", TODAY()-30, TODAY()),{""color"",""blue"";""linewidth"",2}) "),"") | M8: =IFERROR(__xludf.DUMMYFUNCTION("GOOGLEFINANCE(A8,""currency"")"),"USD") -> USD | N8: =round(D8/AE8-1,4) -> 0.0078 | O8: =IFERROR(__xludf.DUMMYFUNCTION("GOOGLEFINANCE(A8,""Change"")"),0.05) -> 0.05 | P8: =IFERROR(__xludf.DUMMYFUNCTION("GOOGLEFINANCE(A8,""High"")"),7.8) -> 7.8 | Q8: =IFERROR(__xludf.DUMMYFUNCTION("GOOGLEFINANCE(A8,""low"")"),7.52) -> 7.52 | R8: =IFERROR(__xludf.DUMMYFUNCTION("abs(P8-Q8)/GOOGLEFINANCE(A8,""closeyest"")"),0.03650586701434162) -> 0.036505867 | S8: =D8/Y8-1 -> 0.56795132 | T8: 76 | W8: =IF(ISERROR(if(or(AND(Q8<=T8,T8<=P8),AND(Q8<=U8, U8<=P8)),"TRADE ALERT","")),"DATA UNAVAILABLE",if(or(AND(Q8<=T8,T8<=P8),T8>P8,AND(Q8<=U8, U8<=P8)),"TRADE ALERT"&" - Price level hit for "&A8&" currently at "&D8&" "&B8,"")) -> TRADE ALERT - Price level hit for KODK currently at 7.73 Eastman Kodak Co | X8: =IFERROR(__xludf.DUMMYFUNCTION("GOOGLEFINANCE($A8,X$3)"),1.47) -> 1.47 | Y8: =IFERROR(__xludf.DUMMYFUNCTION("GOOGLEFINANCE($A8,Y$3)"),4.93) -> 4.93 | Z8: =IFERROR(__xludf.DUMMYFUNCTION("GOOGLEFINANCE($A8,Z$3)"),9.96) -> 9.96 | AA8: =IFERROR(__xludf.DUMMYFUNCTION("GOOGLEFINANCE($A8,AA$3)"),"#N/A") -> #N/A | AB8: =IFERROR(__xludf.DUMMYFUNCTION("GOOGLEFINANCE($A8,AB$3)"),"#N/A") -> #N/A | AC8: =IFERROR(__xludf.DUMMYFUNCTION("GOOGLEFINANCE($A8,AC$3)"),0.0) -> 0 | AD8: =IFERROR(__xludf.DUMMYFUNCTION("GOOGLEFINANCE($A8,AD$3)"),7.4468999E8) -> 744689990 | AE8: =IFERROR(__xludf.DUMMYFUNCTION("GOOGLEFINANCE($A8,AE$3)"),7.67) -> 7.67
B9: =IFERROR(__xludf.DUMMYFUNCTION("GOOGLEFINANCE(A9,""name"")"),"#N/A") -> #N/A | D9: =IFERROR(__xludf.DUMMYFUNCTION("GOOGLEFINANCE(A9)"),"#N/A") -> #N/A | F9: =IF(M9="USD",E9/1.21,E9) -> #N/A | H9: =IFERROR(__xludf.DUMMYFUNCTION("if(isblank(A9)=TRUE,0,if(M9=""GBX"",F9*G9/100,IF(M9=""EUR"",F9*G9/GOOGLEFINANCE(""CURRENCY:GBPEUR""),F9*G9/GOOGLEFINANCE(""CURRENCY:GBPUSD""))))"),0.0) -> 0 | I9: =IFERROR(__xludf.DUMMYFUNCTION("if(isblank(A9)=TRUE,0,if(M9=""GBX"",D9*G9/100,IF(M9=""EUR"",D9*G9/GOOGLEFINANCE(""CURRENCY:GBPEUR""),D9*G9/GOOGLEFINANCE(""CURRENCY:GBPUSD""))))"),0.0) -> 0 | J9: =H9/$B$1 -> 0 | K9: =I9/H9-1 -> #DIV/0! | L9: =IFERROR(__xludf.DUMMYFUNCTION("SPARKLINE(GoogleFinance(A9, ""price"", TODAY()-30, TODAY()),{""color"",""blue"";""linewidth"",2}) "),"#N/A") -> #N/A | M9: =IFERROR(__xludf.DUMMYFUNCTION("GOOGLEFINANCE(A9,""currency"")"),"#N/A") -> #N/A | N9: =round(D9/AE9-1,4) -> #N/A | O9: =IFERROR(__xludf.DUMMYFUNCTION("GOOGLEFINANCE(A9,""Change"")"),"#N/A") -> #N/A | P9: =IFERROR(__xludf.DUMMYFUNCTION("GOOGLEFINANCE(A9,""High"")"),"#N/A") -> #N/A | Q9: =IFERROR(__xludf.DUMMYFUNCTION("GOOGLEFINANCE(A9,""low"")"),"#N/A") -> #N/A | R9: =IFERROR(__xludf.DUMMYFUNCTION("abs(P9-Q9)/GOOGLEFINANCE(A9,""closeyest"")"),"#N/A") -> #N/A | S9: =D9/Y9-1 -> #N/A | T9: 15 | W9: =IF(ISERROR(if(or(AND(Q9<=T9,T9<=P9),AND(Q9<=U9, U9<=P9)),"TRADE ALERT","")),"DATA UNAVAILABLE",if(or(AND(Q9<=T9,T9<=P9),T9>P9,AND(Q9<=U9, U9<=P9)),"TRADE ALERT"&" - Price level hit for "&A9&" currently at "&D9&" "&B9,"")) -> DATA UNAVAILABLE | X9: =IFERROR(__xludf.DUMMYFUNCTION("GOOGLEFINANCE($A9,X$3)"),"#N/A") -> #N/A | Y9: =IFERROR(__xludf.DUMMYFUNCTION("GOOGLEFINANCE($A9,Y$3)"),"#N/A") -> #N/A | Z9: =IFERROR(__xludf.DUMMYFUNCTION("GOOGLEFINANCE($A9,Z$3)"),"#N/A") -> #N/A | AA9: =IFERROR(__xludf.DUMMYFUNCTION("GOOGLEFINANCE($A9,AA$3)"),"#N/A") -> #N/A | AB9: =IFERROR(__xludf.DUMMYFUNCTION("GOOGLEFINANCE($A9,AB$3)"),"#N/A") -> #N/A | AC9: =IFERROR(__xludf.DUMMYFUNCTION("GOOGLEFINANCE($A9,AC$3)"),"#N/A") -> #N/A | AD9: =IFERROR(__xludf.DUMMYFUNCTION("GOOGLEFINANCE($A9,AD$3)"),"#N/A") -> #N/A | AE9: =IFERROR(__xludf.DUMMYFUNCTION("GOOGLEFINANCE($A9,AE$3)"),"#N/A") -> #N/A
B10: =IFERROR(__xludf.DUMMYFUNCTION("GOOGLEFINANCE(A10,""name"")"),"#N/A") -> #N/A | D10: =IFERROR(__xludf.DUMMYFUNCTION("GOOGLEFINANCE(A10)"),"#N/A") -> #N/A | F10: =IF(M10="USD",E10/1.21,E10) -> #N/A | H10: =IFERROR(__xludf.DUMMYFUNCTION("if(isblank(A10)=TRUE,0,if(M10=""GBX"",F10*G10/100,IF(M10=""EUR"",F10*G10/GOOGLEFINANCE(""CURRENCY:GBPEUR""),F10*G10/GOOGLEFINANCE(""CURRENCY:GBPUSD""))))"),0.0) -> 0 | I10: =IFERROR(__xludf.DUMMYFUNCTION("if(isblank(A10)=TRUE,0,if(M10=""GBX"",D10*G10/100,IF(M10=""EUR"",D10*G10/GOOGLEFINANCE(""CURRENCY:GBPEUR""),D10*G10/GOOGLEFINANCE(""CURRENCY:GBPUSD""))))"),0.0) -> 0 | J10: =H10/$B$1 -> 0 | K10: =I10/H10-1 -> #DIV/0! | L10: =IFERROR(__xludf.DUMMYFUNCTION("SPARKLINE(GoogleFinance(A10, ""price"", TODAY()-30, TODAY()),{""color"",""blue"";""linewidth"",2}) "),"#N/A") -> #N/A | M10: =IFERROR(__xludf.DUMMYFUNCTION("GOOGLEFINANCE(A10,""currency"")"),"#N/A") -> #N/A | N10: =round(D10/AE10-1,4) -> #N/A | O10: =IFERROR(__xludf.DUMMYFUNCTION("GOOGLEFINANCE(A10,""Change"")"),"#N/A") -> #N/A | P10: =IFERROR(__xludf.DUMMYFUNCTION("GOOGLEFINANCE(A10,""High"")"),"#N/A") -> #N/A | Q10: =IFERROR(__xludf.DUMMYFUNCTION("GOOGLEFINANCE(A10,""low"")"),"#N/A") -> #N/A | R10: =IFERROR(__xludf.DUMMYFUNCTION("abs(P10-Q10)/GOOGLEFINANCE(A10,""closeyest"")"),"#N/A") -> #N/A | S10: =D10/Y10-1 -> #N/A | T10: 6 | W10: =IF(ISERROR(if(or(AND(Q10<=T10,T10<=P10),AND(Q10<=U10, U10<=P10)),"TRADE ALERT","")),"DATA UNAVAILABLE",if(or(AND(Q10<=T10,T10<=P10),T10>P10,AND(Q10<=U10, U10<=P10)),"TRADE ALERT"&" - Price level hit for "&A10&" currently at "&D10&" "&B10,"")) -> DATA UNAVAILABLE | X10: =IFERROR(__xludf.DUMMYFUNCTION("GOOGLEFINANCE($A10,X$3)"),"#N/A") -> #N/A | Y10: =IFERROR(__xludf.DUMMYFUNCTION("GOOGLEFINANCE($A10,Y$3)"),"#N/A") -> #N/A | Z10: =IFERROR(__xludf.DUMMYFUNCTION("GOOGLEFINANCE($A10,Z$3)"),"#N/A") -> #N/A | AA10: =IFERROR(__xludf.DUMMYFUNCTION("GOOGLEFINANCE($A10,AA$3)"),"#N/A") -> #N/A | AB10: =IFERROR(__xludf.DUMMYFUNCTION("GOOGLEFINANCE($A10,AB$3)"),"#N/A") -> #N/A | AC10: =IFERROR(__xludf.DUMMYFUNCTION("GOOGLEFINANCE($A10,AC$3)"),"#N/A") -> #N/A | AD10: =IFERROR(__xludf.DUMMYFUNCTION("GOOGLEFINANCE($A10,AD$3)"),"#N/A") -> #N/A | AE10: =IFERROR(__xludf.DUMMYFUNCTION("GOOGLEFINANCE($A10,AE$3)"),"#N/A") -> #N/A
B11: =IFERROR(__xludf.DUMMYFUNCTION("GOOGLEFINANCE(A11,""name"")"),"#N/A") -> #N/A | D11: =IFERROR(__xludf.DUMMYFUNCTION("GOOGLEFINANCE(A11)"),"#N/A") -> #N/A | F11: =IF(M11="USD",E11/1.21,E11) -> #N/A | H11: =IFERROR(__xludf.DUMMYFUNCTION("if(isblank(A11)=TRUE,0,if(M11=""GBX"",F11*G11/100,IF(M11=""EUR"",F11*G11/GOOGLEFINANCE(""CURRENCY:GBPEUR""),F11*G11/GOOGLEFINANCE(""CURRENCY:GBPUSD""))))"),0.0) -> 0 | I11: =IFERROR(__xludf.DUMMYFUNCTION("if(isblank(A11)=TRUE,0,if(M11=""GBX"",D11*G11/100,IF(M11=""EUR"",D11*G11/GOOGLEFINANCE(""CURRENCY:GBPEUR""),D11*G11/GOOGLEFINANCE(""CURRENCY:GBPUSD""))))"),0.0) -> 0 | J11: =H11/$B$1 -> 0 | K11: =I11/H11-1 -> #DIV/0! | L11: =IFERROR(__xludf.DUMMYFUNCTION("SPARKLINE(GoogleFinance(A11, ""price"", TODAY()-30, TODAY()),{""color"",""blue"";""linewidth"",2}) "),"#N/A") -> #N/A | M11: =IFERROR(__xludf.DUMMYFUNCTION("GOOGLEFINANCE(A11,""currency"")"),"#N/A") -> #N/A | N11: =round(D11/AE11-1,4) -> #N/A | O11: =IFERROR(__xludf.DUMMYFUNCTION("GOOGLEFINANCE(A11,""Change"")"),"#N/A") -> #N/A | P11: =IFERROR(__xludf.DUMMYFUNCTION("GOOGLEFINANCE(A11,""High"")"),"#N/A") -> #N/A | Q11: =IFERROR(__xludf.DUMMYFUNCTION("GOOGLEFINANCE(A11,""low"")"),"#N/A") -> #N/A | R11: =IFERROR(__xludf.DUMMYFUNCTION("abs(P11-Q11)/GOOGLEFINANCE(A11,""closeyest"")"),"#N/A") -> #N/A | S11: =D11/Y11-1 -> #N/A | T11: 36 | W11: =IF(ISERROR(if(or(AND(Q11<=T11,T11<=P11),AND(Q11<=U11, U11<=P11)),"TRADE ALERT","")),"DATA UNAVAILABLE",if(or(AND(Q11<=T11,T11<=P11),T11>P11,AND(Q11<=U11, U11<=P11)),"TRADE ALERT"&" - Price level hit for "&A11&" currently at "&D11&" "&B11,"")) -> DATA UNAVAILABLE | X11: =IFERROR(__xludf.DUMMYFUNCTION("GOOGLEFINANCE($A11,X$3)"),"#N/A") -> #N/A | Y11: =IFERROR(__xludf.DUMMYFUNCTION("GOOGLEFINANCE($A11,Y$3)"),"#N/A") -> #N/A | Z11: =IFERROR(__xludf.DUMMYFUNCTION("GOOGLEFINANCE($A11,Z$3)"),"#N/A") -> #N/A | AA11: =IFERROR(__xludf.DUMMYFUNCTION("GOOGLEFINANCE($A11,AA$3)"),"#N/A") -> #N/A | AB11: =IFERROR(__xludf.DUMMYFUNCTION("GOOGLEFINANCE($A11,AB$3)"),"#N/A") -> #N/A | AC11: =IFERROR(__xludf.DUMMYFUNCTION("GOOGLEFINANCE($A11,AC$3)"),"#N/A") -> #N/A | AD11: =IFERROR(__xludf.DUMMYFUNCTION("GOOGLEFINANCE($A11,AD$3)"),"#N/A") -> #N/A | AE11: =IFERROR(__xludf.DUMMYFUNCTION("GOOGLEFINANCE($A11,AE$3)"),"#N/A") -> #N/A
B12: =IFERROR(__xludf.DUMMYFUNCTION("GOOGLEFINANCE(A12,""name"")"),"#N/A") -> #N/A | D12: =IFERROR(__xludf.DUMMYFUNCTION("GOOGLEFINANCE(A12)"),"#N/A") -> #N/A | F12: =IF(M12="USD",E12/1.21,E12) -> #N/A | H12: =IFERROR(__xludf.DUMMYFUNCTION("if(isblank(A12)=TRUE,0,if(M12=""GBX"",F12*G12/100,IF(M12=""EUR"",F12*G12/GOOGLEFINANCE(""CURRENCY:GBPEUR""),F12*G12/GOOGLEFINANCE(""CURRENCY:GBPUSD""))))"),0.0) -> 0 | I12: =IFERROR(__xludf.DUMMYFUNCTION("if(isblank(A12)=TRUE,0,if(M12=""GBX"",D12*G12/100,IF(M12=""EUR"",D12*G12/GOOGLEFINANCE(""CURRENCY:GBPEUR""),D12*G12/GOOGLEFINANCE(""CURRENCY:GBPUSD""))))"),0.0) -> 0 | J12: =H12/$B$1 -> 0 | K12: =I12/H12-1 -> #DIV/0! | L12: =IFERROR(__xludf.DUMMYFUNCTION("SPARKLINE(GoogleFinance(A12, ""price"", TODAY()-30, TODAY()),{""color"",""blue"";""linewidth"",2}) "),"#N/A") -> #N/A | M12: =IFERROR(__xludf.DUMMYFUNCTION("GOOGLEFINANCE(A12,""currency"")"),"#N/A") -> #N/A | N12: =round(D12/AE12-1,4) -> #N/A | O12: =IFERROR(__xludf.DUMMYFUNCTION("GOOGLEFINANCE(A12,""Change"")"),"#N/A") -> #N/A | P12: =IFERROR(__xludf.DUMMYFUNCTION("GOOGLEFINANCE(A12,""High"")"),"#N/A") -> #N/A | Q12: =IFERROR(__xludf.DUMMYFUNCTION("GOOGLEFINANCE(A12,""low"")"),"#N/A") -> #N/A | R12: =IFERROR(__xludf.DUMMYFUNCTION("abs(P12-Q12)/GOOGLEFINANCE(A12,""closeyest"")"),"#N/A") -> #N/A | S12: =D12/Y12-1 -> #N/A | T12: 31.28 | W12: =IF(ISERROR(if(or(AND(Q12<=T12,T12<=P12),AND(Q12<=U12, U12<=P12)),"TRADE ALERT","")),"DATA UNAVAILABLE",if(or(AND(Q12<=T12,T12<=P12),T12>P12,AND(Q12<=U12, U12<=P12)),"TRADE ALERT"&" - Price level hit for "&A12&" currently at "&D12&" "&B12,"")) -> DATA UNAVAILABLE | X12: =IFERROR(__xludf.DUMMYFUNCTION("GOOGLEFINANCE($A12,X$3)"),"#N/A") -> #N/A | Y12: =IFERROR(__xludf.DUMMYFUNCTION("GOOGLEFINANCE($A12,Y$3)"),"#N/A") -> #N/A | Z12: =IFERROR(__xludf.DUMMYFUNCTION("GOOGLEFINANCE($A12,Z$3)"),"#N/A") -> #N/A | AA12: =IFERROR(__xludf.DUMMYFUNCTION("GOOGLEFINANCE($A12,AA$3)"),"#N/A") -> #N/A | AB12: =IFERROR(__xludf.DUMMYFUNCTION("GOOGLEFINANCE($A12,AB$3)"),"#N/A") -> #N/A | AC12: =IFERROR(__xludf.DUMMYFUNCTION("GOOGLEFINANCE($A12,AC$3)"),"#N/A") -> #N/A | AD12: =IFERROR(__xludf.DUMMYFUNCTION("GOOGLEFINANCE($A12,AD$3)"),"#N/A") -> #N/A | AE12: =IFERROR(__xludf.DUMMYFUNCTION("GOOGLEFINANCE($A12,AE$3)"),"#N/A") -> #N/A
B13: =IFERROR(__xludf.DUMMYFUNCTION("GOOGLEFINANCE(A13,""name"")"),"#N/A") -> #N/A | D13: =IFERROR(__xludf.DUMMYFUNCTION("GOOGLEFINANCE(A13)"),"#N/A") -> #N/A | F13: =IF(M13="USD",E13/1.21,E13) -> #N/A | H13: =IFERROR(__xludf.DUMMYFUNCTION("if(isblank(A13)=TRUE,0,if(M13=""GBX"",F13*G13/100,IF(M13=""EUR"",F13*G13/GOOGLEFINANCE(""CURRENCY:GBPEUR""),F13*G13/GOOGLEFINANCE(""CURRENCY:GBPUSD""))))"),0.0) -> 0 | I13: =IFERROR(__xludf.DUMMYFUNCTION("if(isblank(A13)=TRUE,0,if(M13=""GBX"",D13*G13/100,IF(M13=""EUR"",D13*G13/GOOGLEFINANCE(""CURRENCY:GBPEUR""),D13*G13/GOOGLEFINANCE(""CURRENCY:GBPUSD""))))"),0.0) -> 0 | J13: =H13/$B$1 -> 0 | K13: =I13/H13-1 -> #DIV/0! | L13: =IFERROR(__xludf.DUMMYFUNCTION("SPARKLINE(GoogleFinance(A13, ""price"", TODAY()-30, TODAY()),{""color"",""blue"";""linewidth"",2}) "),"#N/A") -> #N/A | M13: =IFERROR(__xludf.DUMMYFUNCTION("GOOGLEFINANCE(A13,""currency"")"),"#N/A") -> #N/A | N13: =round(D13/AE13-1,4) -> #N/A | O13: =IFERROR(__xludf.DUMMYFUNCTION("GOOGLEFINANCE(A13,""Change"")"),"#N/A") -> #N/A | P13: =IFERROR(__xludf.DUMMYFUNCTION("GOOGLEFINANCE(A13,""High"")"),"#N/A") -> #N/A | Q13: =IFERROR(__xludf.DUMMYFUNCTION("GOOGLEFINANCE(A13,""low"")"),"#N/A") -> #N/A | R13: =IFERROR(__xludf.DUMMYFUNCTION("abs(P13-Q13)/GOOGLEFINANCE(A13,""closeyest"")"),"#N/A") -> #N/A | S13: =D13/Y13-1 -> #N/A | T13: 1.39 | W13: =IF(ISERROR(if(or(AND(Q13<=T13,T13<=P13),AND(Q13<=U13, U13<=P13)),"TRADE ALERT","")),"DATA UNAVAILABLE",if(or(AND(Q13<=T13,T13<=P13),T13>P13,AND(Q13<=U13, U13<=P13)),"TRADE ALERT"&" - Price level hit for "&A13&" currently at "&D13&" "&B13,"")) -> DATA UNAVAILABLE | X13: =IFERROR(__xludf.DUMMYFUNCTION("GOOGLEFINANCE($A13,X$3)"),"#N/A") -> #N/A | Y13: =IFERROR(__xludf.DUMMYFUNCTION("GOOGLEFINANCE($A13,Y$3)"),"#N/A") -> #N/A | Z13: =IFERROR(__xludf.DUMMYFUNCTION("GOOGLEFINANCE($A13,Z$3)"),"#N/A") -> #N/A | AA13: =IFERROR(__xludf.DUMMYFUNCTION("GOOGLEFINANCE($A13,AA$3)"),"#N/A") -> #N/A | AB13: =IFERROR(__xludf.DUMMYFUNCTION("GOOGLEFINANCE($A13,AB$3)"),"#N/A") -> #N/A | AC13: =IFERROR(__xludf.DUMMYFUNCTION("GOOGLEFINANCE($A13,AC$3)"),"#N/A") -> #N/A | AD13: =IFERROR(__xludf.DUMMYFUNCTION("GOOGLEFINANCE($A13,AD$3)"),"#N/A") -> #N/A | AE13: =IFERROR(__xludf.DUMMYFUNCTION("GOOGLEFINANCE($A13,AE$3)"),"#N/A") -> #N/A
B14: =IFERROR(__xludf.DUMMYFUNCTION("GOOGLEFINANCE(A14,""name"")"),"#N/A") -> #N/A | D14: =IFERROR(__xludf.DUMMYFUNCTION("GOOGLEFINANCE(A14)"),"#N/A") -> #N/A | F14: =IF(M14="USD",E14/1.21,E14) -> #N/A | H14: =IFERROR(__xludf.DUMMYFUNCTION("if(isblank(A14)=TRUE,0,if(M14=""GBX"",F14*G14/100,IF(M14=""EUR"",F14*G14/GOOGLEFINANCE(""CURRENCY:GBPEUR""),F14*G14/GOOGLEFINANCE(""CURRENCY:GBPUSD""))))"),0.0) -> 0 | I14: =IFERROR(__xludf.DUMMYFUNCTION("if(isblank(A14)=TRUE,0,if(M14=""GBX"",D14*G14/100,IF(M14=""EUR"",D14*G14/GOOGLEFINANCE(""CURRENCY:GBPEUR""),D14*G14/GOOGLEFINANCE(""CURRENCY:GBPUSD""))))"),0.0) -> 0 | J14: =H14/$B$1 -> 0 | K14: =I14/H14-1 -> #DIV/0! | L14: =IFERROR(__xludf.DUMMYFUNCTION("SPARKLINE(GoogleFinance(A14, ""price"", TODAY()-30, TODAY()),{""color"",""blue"";""linewidth"",2}) "),"#N/A") -> #N/A | M14: =IFERROR(__xludf.DUMMYFUNCTION("GOOGLEFINANCE(A14,""currency"")"),"#N/A") -> #N/A | N14: =round(D14/AE14-1,4) -> #N/A | O14: =IFERROR(__xludf.DUMMYFUNCTION("GOOGLEFINANCE(A14,""Change"")"),"#N/A") -> #N/A | P14: =IFERROR(__xludf.DUMMYFUNCTION("GOOGLEFINANCE(A14,""High"")"),"#N/A") -> #N/A | Q14: =IFERROR(__xludf.DUMMYFUNCTION("GOOGLEFINANCE(A14,""low"")"),"#N/A") -> #N/A | R14: =IFERROR(__xludf.DUMMYFUNCTION("abs(P14-Q14)/GOOGLEFINANCE(A14,""closeyest"")"),"#N/A") -> #N/A | S14: =D14/Y14-1 -> #N/A | T14: 380 | W14: =IF(ISERROR(if(or(AND(Q14<=T14,T14<=P14),AND(Q14<=U14, U14<=P14)),"TRADE ALERT","")),"DATA UNAVAILABLE",if(or(AND(Q14<=T14,T14<=P14),T14>P14,AND(Q14<=U14, U14<=P14)),"TRADE ALERT"&" - Price level hit for "&A14&" currently at "&D14&" "&B14,"")) -> DATA UNAVAILABLE | X14: =IFERROR(__xludf.DUMMYFUNCTION("GOOGLEFINANCE($A14,X$3)"),"#N/A") -> #N/A | Y14: =IFERROR(__xludf.DUMMYFUNCTION("GOOGLEFINANCE($A14,Y$3)"),"#N/A") -> #N/A | Z14: =IFERROR(__xludf.DUMMYFUNCTION("GOOGLEFINANCE($A14,Z$3)"),"#N/A") -> #N/A | AA14: =IFERROR(__xludf.DUMMYFUNCTION("GOOGLEFINANCE($A14,AA$3)"),"#N/A") -> #N/A | AB14: =IFERROR(__xludf.DUMMYFUNCTION("GOOGLEFINANCE($A14,AB$3)"),"#N/A") -> #N/A | AC14: =IFERROR(__xludf.DUMMYFUNCTION("GOOGLEFINANCE($A14,AC$3)"),"#N/A") -> #N/A | AD14: =IFERROR(__xludf.DUMMYFUNCTION("GOOGLEFINANCE($A14,AD$3)"),"#N/A") -> #N/A | AE14: =IFERROR(__xludf.DUMMYFUNCTION("GOOGLEFINANCE($A14,AE$3)"),"#N/A") -> #N/A
B15: =IFERROR(__xludf.DUMMYFUNCTION("GOOGLEFINANCE(A15,""name"")"),"#N/A") -> #N/A | D15: =IFERROR(__xludf.DUMMYFUNCTION("GOOGLEFINANCE(A15)"),"#N/A") -> #N/A | F15: =IF(M15="USD",E15/1.21,E15) -> #N/A | H15: =IFERROR(__xludf.DUMMYFUNCTION("if(isblank(A15)=TRUE,0,if(M15=""GBX"",F15*G15/100,IF(M15=""EUR"",F15*G15/GOOGLEFINANCE(""CURRENCY:GBPEUR""),F15*G15/GOOGLEFINANCE(""CURRENCY:GBPUSD""))))"),0.0) -> 0 | I15: =IFERROR(__xludf.DUMMYFUNCTION("if(isblank(A15)=TRUE,0,if(M15=""GBX"",D15*G15/100,IF(M15=""EUR"",D15*G15/GOOGLEFINANCE(""CURRENCY:GBPEUR""),D15*G15/GOOGLEFINANCE(""CURRENCY:GBPUSD""))))"),0.0) -> 0 | J15: =H15/$B$1 -> 0 | K15: =I15/H15-1 -> #DIV/0! | L15: =IFERROR(__xludf.DUMMYFUNCTION("SPARKLINE(GoogleFinance(A15, ""price"", TODAY()-30, TODAY()),{""color"",""blue"";""linewidth"",2}) "),"#N/A") -> #N/A | M15: =IFERROR(__xludf.DUMMYFUNCTION("GOOGLEFINANCE(A15,""currency"")"),"#N/A") -> #N/A | N15: =round(D15/AE15-1,4) -> #N/A | O15: =IFERROR(__xludf.DUMMYFUNCTION("GOOGLEFINANCE(A15,""Change"")"),"#N/A") -> #N/A | P15: =IFERROR(__xludf.DUMMYFUNCTION("GOOGLEFINANCE(A15,""High"")"),"#N/A") -> #N/A | Q15: =IFERROR(__xludf.DUMMYFUNCTION("GOOGLEFINANCE(A15,""low"")"),"#N/A") -> #N/A | R15: =IFERROR(__xludf.DUMMYFUNCTION("abs(P15-Q15)/GOOGLEFINANCE(A15,""closeyest"")"),"#N/A") -> #N/A | S15: =D15/Y15-1 -> #N/A | W15: =IF(ISERROR(if(or(AND(Q15<=T15,T15<=P15),AND(Q15<=U15, U15<=P15)),"TRADE ALERT","")),"DATA UNAVAILABLE",if(or(AND(Q15<=T15,T15<=P15),T15>P15,AND(Q15<=U15, U15<=P15)),"TRADE ALERT"&" - Price level hit for "&A15&" currently at "&D15&" "&B15,"")) -> DATA UNAVAILABLE | X15: =IFERROR(__xludf.DUMMYFUNCTION("GOOGLEFINANCE($A15,X$3)"),"#N/A") -> #N/A | Y15: =IFERROR(__xludf.DUMMYFUNCTION("GOOGLEFINANCE($A15,Y$3)"),"#N/A") -> #N/A | Z15: =IFERROR(__xludf.DUMMYFUNCTION("GOOGLEFINANCE($A15,Z$3)"),"#N/A") -> #N/A | AA15: =IFERROR(__xludf.DUMMYFUNCTION("GOOGLEFINANCE($A15,AA$3)"),"#N/A") -> #N/A | AB15: =IFERROR(__xludf.DUMMYFUNCTION("GOOGLEFINANCE($A15,AB$3)"),"#N/A") -> #N/A | AC15: =IFERROR(__xludf.DUMMYFUNCTION("GOOGLEFINANCE($A15,AC$3)"),"#N/A") -> #N/A | AD15: =IFERROR(__xludf.DUMMYFUNCTION("GOOGLEFINANCE($A15,AD$3)"),"#N/A") -> #N/A | AE15: =IFERROR(__xludf.DUMMYFUNCTION("GOOGLEFINANCE($A15,AE$3)"),"#N/A") -> #N/A
B16: =IFERROR(__xludf.DUMMYFUNCTION("GOOGLEFINANCE(A16,""name"")"),"#N/A") -> #N/A | D16: =IFERROR(__xludf.DUMMYFUNCTION("GOOGLEFINANCE(A16)"),"#N/A") -> #N/A | F16: =IF(M16="USD",E16/1.21,E16) -> #N/A | H16: =IFERROR(__xludf.DUMMYFUNCTION("if(isblank(A16)=TRUE,0,if(M16=""GBX"",F16*G16/100,IF(M16=""EUR"",F16*G16/GOOGLEFINANCE(""CURRENCY:GBPEUR""),F16*G16/GOOGLEFINANCE(""CURRENCY:GBPUSD""))))"),0.0) -> 0 | I16: =IFERROR(__xludf.DUMMYFUNCTION("if(isblank(A16)=TRUE,0,if(M16=""GBX"",D16*G16/100,IF(M16=""EUR"",D16*G16/GOOGLEFINANCE(""CURRENCY:GBPEUR""),D16*G16/GOOGLEFINANCE(""CURRENCY:GBPUSD""))))"),0.0) -> 0 | J16: =H16/$B$1 -> 0 | K16: =I16/H16-1 -> #DIV/0! | L16: =IFERROR(__xludf.DUMMYFUNCTION("SPARKLINE(GoogleFinance(A16, ""price"", TODAY()-30, TODAY()),{""color"",""blue"";""linewidth"",2}) "),"#N/A") -> #N/A | M16: =IFERROR(__xludf.DUMMYFUNCTION("GOOGLEFINANCE(A16,""currency"")"),"#N/A") -> #N/A | N16: =round(D16/AE16-1,4) -> #N/A | O16: =IFERROR(__xludf.DUMMYFUNCTION("GOOGLEFINANCE(A16,""Change"")"),"#N/A") -> #N/A | P16: =IFERROR(__xludf.DUMMYFUNCTION("GOOGLEFINANCE(A16,""High"")"),"#N/A") -> #N/A | Q16: =IFERROR(__xludf.DUMMYFUNCTION("GOOGLEFINANCE(A16,""low"")"),"#N/A") -> #N/A | R16: =IFERROR(__xludf.DUMMYFUNCTION("abs(P16-Q16)/GOOGLEFINANCE(A16,""closeyest"")"),"#N/A") -> #N/A | S16: =D16/Y16-1 -> #N/A | W16: =IF(ISERROR(if(or(AND(Q16<=T16,T16<=P16),AND(Q16<=U16, U16<=P16)),"TRADE ALERT","")),"DATA UNAVAILABLE",if(or(AND(Q16<=T16,T16<=P16),T16>P16,AND(Q16<=U16, U16<=P16)),"TRADE ALERT"&" - Price level hit for "&A16&" currently at "&D16&" "&B16,"")) -> DATA UNAVAILABLE | X16: =IFERROR(__xludf.DUMMYFUNCTION("GOOGLEFINANCE($A16,X$3)"),"#N/A") -> #N/A | Y16: =IFERROR(__xludf.DUMMYFUNCTION("GOOGLEFINANCE($A16,Y$3)"),"#N/A") -> #N/A | Z16: =IFERROR(__xludf.DUMMYFUNCTION("GOOGLEFINANCE($A16,Z$3)"),"#N/A") -> #N/A | AA16: =IFERROR(__xludf.DUMMYFUNCTION("GOOGLEFINANCE($A16,AA$3)"),"#N/A") -> #N/A | AB16: =IFERROR(__xludf.DUMMYFUNCTION("GOOGLEFINANCE($A16,AB$3)"),"#N/A") -> #N/A | AC16: =IFERROR(__xludf.DUMMYFUNCTION("GOOGLEFINANCE($A16,AC$3)"),"#N/A") -> #N/A | AD16: =IFERROR(__xludf.DUMMYFUNCTION("GOOGLEFINANCE($A16,AD$3)"),"#N/A") -> #N/A | AE16: =IFERROR(__xludf.DUMMYFUNCTION("GOOGLEFINANCE($A16,AE$3)"),"#N/A") -> #N/A
B17: =IFERROR(__xludf.DUMMYFUNCTION("GOOGLEFINANCE(A17,""name"")"),"#N/A") -> #N/A | D17: =IFERROR(__xludf.DUMMYFUNCTION("GOOGLEFINANCE(A17)"),"#N/A") -> #N/A | F17: =IF(M17="USD",E17/1.21,E17) -> #N/A | H17: =IFERROR(__xludf.DUMMYFUNCTION("if(isblank(A17)=TRUE,0,if(M17=""GBX"",F17*G17/100,IF(M17=""EUR"",F17*G17/GOOGLEFINANCE(""CURRENCY:GBPEUR""),F17*G17/GOOGLEFINANCE(""CURRENCY:GBPUSD""))))"),0.0) -> 0 | I17: =IFERROR(__xludf.DUMMYFUNCTION("if(isblank(A17)=TRUE,0,if(M17=""GBX"",D17*G17/100,IF(M17=""EUR"",D17*G17/GOOGLEFINANCE(""CURRENCY:GBPEUR""),D17*G17/GOOGLEFINANCE(""CURRENCY:GBPUSD""))))"),0.0) -> 0 | J17: =H17/$B$1 -> 0 | K17: =I17/H17-1 -> #DIV/0! | L17: =IFERROR(__xludf.DUMMYFUNCTION("SPARKLINE(GoogleFinance(A17, ""price"", TODAY()-30, TODAY()),{""color"",""blue"";""linewidth"",2}) "),"#N/A") -> #N/A | M17: =IFERROR(__xludf.DUMMYFUNCTION("GOOGLEFINANCE(A17,""currency"")"),"#N/A") -> #N/A | N17: =round(D17/AE17-1,4) -> #N/A | O17: =IFERROR(__xludf.DUMMYFUNCTION("GOOGLEFINANCE(A17,""Change"")"),"#N/A") -> #N/A | P17: =IFERROR(__xludf.DUMMYFUNCTION("GOOGLEFINANCE(A17,""High"")"),"#N/A") -> #N/A | Q17: =IFERROR(__xludf.DUMMYFUNCTION("GOOGLEFINANCE(A17,""low"")"),"#N/A") -> #N/A | R17: =IFERROR(__xludf.DUMMYFUNCTION("abs(P17-Q17)/GOOGLEFINANCE(A17,""closeyest"")"),"#N/A") -> #N/A | S17: =D17/Y17-1 -> #N/A | W17: =IF(ISERROR(if(or(AND(Q17<=T17,T17<=P17),AND(Q17<=U17, U17<=P17)),"TRADE ALERT","")),"DATA UNAVAILABLE",if(or(AND(Q17<=T17,T17<=P17),T17>P17,AND(Q17<=U17, U17<=P17)),"TRADE ALERT"&" - Price level hit for "&A17&" currently at "&D17&" "&B17,"")) -> DATA UNAVAILABLE | X17: =IFERROR(__xludf.DUMMYFUNCTION("GOOGLEFINANCE($A17,X$3)"),"#N/A") -> #N/A | Y17: =IFERROR(__xludf.DUMMYFUNCTION("GOOGLEFINANCE($A17,Y$3)"),"#N/A") -> #N/A | Z17: =IFERROR(__xludf.DUMMYFUNCTION("GOOGLEFINANCE($A17,Z$3)"),"#N/A") -> #N/A | AA17: =IFERROR(__xludf.DUMMYFUNCTION("GOOGLEFINANCE($A17,AA$3)"),"#N/A") -> #N/A | AB17: =IFERROR(__xludf.DUMMYFUNCTION("GOOGLEFINANCE($A17,AB$3)"),"#N/A") -> #N/A | AC17: =IFERROR(__xludf.DUMMYFUNCTION("GOOGLEFINANCE($A17,AC$3)"),"#N/A") -> #N/A | AD17: =IFERROR(__xludf.DUMMYFUNCTION("GOOGLEFINANCE($A17,AD$3)"),"#N/A") -> #N/A | AE17: =IFERROR(__xludf.DUMMYFUNCTION("GOOGLEFINANCE($A17,AE$3)"),"#N/A") -> #N/A
B18: =IFERROR(__xludf.DUMMYFUNCTION("GOOGLEFINANCE(A18,""name"")"),"#N/A") -> #N/A | D18: =IFERROR(__xludf.DUMMYFUNCTION("GOOGLEFINANCE(A18)"),"#N/A") -> #N/A | F18: =IF(M18="USD",E18/1.21,E18) -> #N/A | H18: =IFERROR(__xludf.DUMMYFUNCTION("if(isblank(A18)=TRUE,0,if(M18=""GBX"",F18*G18/100,IF(M18=""EUR"",F18*G18/GOOGLEFINANCE(""CURRENCY:GBPEUR""),F18*G18/GOOGLEFINANCE(""CURRENCY:GBPUSD""))))"),0.0) -> 0 | I18: =IFERROR(__xludf.DUMMYFUNCTION("if(isblank(A18)=TRUE,0,if(M18=""GBX"",D18*G18/100,IF(M18=""EUR"",D18*G18/GOOGLEFINANCE(""CURRENCY:GBPEUR""),D18*G18/GOOGLEFINANCE(""CURRENCY:GBPUSD""))))"),0.0) -> 0 | J18: =H18/$B$1 -> 0 | K18: =I18/H18-1 -> #DIV/0! | L18: =IFERROR(__xludf.DUMMYFUNCTION("SPARKLINE(GoogleFinance(A18, ""price"", TODAY()-30, TODAY()),{""color"",""blue"";""linewidth"",2}) "),"#N/A") -> #N/A | M18: =IFERROR(__xludf.DUMMYFUNCTION("GOOGLEFINANCE(A18,""currency"")"),"#N/A") -> #N/A | N18: =round(D18/AE18-1,4) -> #N/A | O18: =IFERROR(__xludf.DUMMYFUNCTION("GOOGLEFINANCE(A18,""Change"")"),"#N/A") -> #N/A | P18: =IFERROR(__xludf.DUMMYFUNCTION("GOOGLEFINANCE(A18,""High"")"),"#N/A") -> #N/A | Q18: =IFERROR(__xludf.DUMMYFUNCTION("GOOGLEFINANCE(A18,""low"")"),"#N/A") -> #N/A | R18: =IFERROR(__xludf.DUMMYFUNCTION("abs(P18-Q18)/GOOGLEFINANCE(A18,""closeyest"")"),"#N/A") -> #N/A | S18: =D18/Y18-1 -> #N/A | W18: =IF(ISERROR(if(or(AND(Q18<=T18,T18<=P18),AND(Q18<=U18, U18<=P18)),"TRADE ALERT","")),"DATA UNAVAILABLE",if(or(AND(Q18<=T18,T18<=P18),T18>P18,AND(Q18<=U18, U18<=P18)),"TRADE ALERT"&" - Price level hit for "&A18&" currently at "&D18&" "&B18,"")) -> DATA UNAVAILABLE | X18: =IFERROR(__xludf.DUMMYFUNCTION("GOOGLEFINANCE($A18,X$3)"),"#N/A") -> #N/A | Y18: =IFERROR(__xludf.DUMMYFUNCTION("GOOGLEFINANCE($A18,Y$3)"),"#N/A") -> #N/A | Z18: =IFERROR(__xludf.DUMMYFUNCTION("GOOGLEFINANCE($A18,Z$3)"),"#N/A") -> #N/A | AA18: =IFERROR(__xludf.DUMMYFUNCTION("GOOGLEFINANCE($A18,AA$3)"),"#N/A") -> #N/A | AB18: =IFERROR(__xludf.DUMMYFUNCTION("GOOGLEFINANCE($A18,AB$3)"),"#N/A") -> #N/A | AC18: =IFERROR(__xludf.DUMMYFUNCTION("GOOGLEFINANCE($A18,AC$3)"),"#N/A") -> #N/A | AD18: =IFERROR(__xludf.DUMMYFUNCTION("GOOGLEFINANCE($A18,AD$3)"),"#N/A") -> #N/A | AE18: =IFERROR(__xludf.DUMMYFUNCTION("GOOGLEFINANCE($A18,AE$3)"),"#N/A") -> #N/A
B19: =IFERROR(__xludf.DUMMYFUNCTION("GOOGLEFINANCE(A19,""name"")"),"#N/A") -> #N/A | D19: =IFERROR(__xludf.DUMMYFUNCTION("GOOGLEFINANCE(A19)"),"#N/A") -> #N/A | F19: =IF(M19="USD",E19/1.21,E19) -> #N/A | H19: =IFERROR(__xludf.DUMMYFUNCTION("if(isblank(A19)=TRUE,0,if(M19=""GBX"",F19*G19/100,IF(M19=""EUR"",F19*G19/GOOGLEFINANCE(""CURRENCY:GBPEUR""),F19*G19/GOOGLEFINANCE(""CURRENCY:GBPUSD""))))"),0.0) -> 0 | I19: =IFERROR(__xludf.DUMMYFUNCTION("if(isblank(A19)=TRUE,0,if(M19=""GBX"",D19*G19/100,IF(M19=""EUR"",D19*G19/GOOGLEFINANCE(""CURRENCY:GBPEUR""),D19*G19/GOOGLEFINANCE(""CURRENCY:GBPUSD""))))"),0.0) -> 0 | J19: =H19/$B$1 -> 0 | K19: =I19/H19-1 -> #DIV/0! | L19: =IFERROR(__xludf.DUMMYFUNCTION("SPARKLINE(GoogleFinance(A19, ""price"", TODAY()-30, TODAY()),{""color"",""blue"";""linewidth"",2}) "),"#N/A") -> #N/A | M19: =IFERROR(__xludf.DUMMYFUNCTION("GOOGLEFINANCE(A19,""currency"")"),"#N/A") -> #N/A | N19: =round(D19/AE19-1,4) -> #N/A | O19: =IFERROR(__xludf.DUMMYFUNCTION("GOOGLEFINANCE(A19,""Change"")"),"#N/A") -> #N/A | P19: =IFERROR(__xludf.DUMMYFUNCTION("GOOGLEFINANCE(A19,""High"")"),"#N/A") -> #N/A | Q19: =IFERROR(__xludf.DUMMYFUNCTION("GOOGLEFINANCE(A19,""low"")"),"#N/A") -> #N/A | R19: =IFERROR(__xludf.DUMMYFUNCTION("abs(P19-Q19)/GOOGLEFINANCE(A19,""closeyest"")"),"#N/A") -> #N/A | S19: =D19/Y19-1 -> #N/A | W19: =IF(ISERROR(if(or(AND(Q19<=T19,T19<=P19),AND(Q19<=U19, U19<=P19)),"TRADE ALERT","")),"DATA UNAVAILABLE",if(or(AND(Q19<=T19,T19<=P19),T19>P19,AND(Q19<=U19, U19<=P19)),"TRADE ALERT"&" - Price level hit for "&A19&" currently at "&D19&" "&B19,"")) -> DATA UNAVAILABLE | X19: =IFERROR(__xludf.DUMMYFUNCTION("GOOGLEFINANCE($A19,X$3)"),"#N/A") -> #N/A | Y19: =IFERROR(__xludf.DUMMYFUNCTION("GOOGLEFINANCE($A19,Y$3)"),"#N/A") -> #N/A | Z19: =IFERROR(__xludf.DUMMYFUNCTION("GOOGLEFINANCE($A19,Z$3)"),"#N/A") -> #N/A | AA19: =IFERROR(__xludf.DUMMYFUNCTION("GOOGLEFINANCE($A19,AA$3)"),"#N/A") -> #N/A | AB19: =IFERROR(__xludf.DUMMYFUNCTION("GOOGLEFINANCE($A19,AB$3)"),"#N/A") -> #N/A | AC19: =IFERROR(__xludf.DUMMYFUNCTION("GOOGLEFINANCE($A19,AC$3)"),"#N/A") -> #N/A | AD19: =IFERROR(__xludf.DUMMYFUNCTION("GOOGLEFINANCE($A19,AD$3)"),"#N/A") -> #N/A | AE19: =IFERROR(__xludf.DUMMYFUNCTION("GOOGLEFINANCE($A19,AE$3)"),"#N/A") -> #N/A
B20: =IFERROR(__xludf.DUMMYFUNCTION("GOOGLEFINANCE(A20,""name"")"),"#N/A") -> #N/A | D20: =IFERROR(__xludf.DUMMYFUNCTION("GOOGLEFINANCE(A20)"),"#N/A") -> #N/A | F20: =IF(M20="USD",E20/1.21,E20) -> #N/A | H20: =IFERROR(__xludf.DUMMYFUNCTION("if(isblank(A20)=TRUE,0,if(M20=""GBX"",F20*G20/100,IF(M20=""EUR"",F20*G20/GOOGLEFINANCE(""CURRENCY:GBPEUR""),F20*G20/GOOGLEFINANCE(""CURRENCY:GBPUSD""))))"),0.0) -> 0 | I20: =IFERROR(__xludf.DUMMYFUNCTION("if(isblank(A20)=TRUE,0,if(M20=""GBX"",D20*G20/100,IF(M20=""EUR"",D20*G20/GOOGLEFINANCE(""CURRENCY:GBPEUR""),D20*G20/GOOGLEFINANCE(""CURRENCY:GBPUSD""))))"),0.0) -> 0 | J20: =H20/$B$1 -> 0 | K20: =I20/H20-1 -> #DIV/0! | L20: =IFERROR(__xludf.DUMMYFUNCTION("SPARKLINE(GoogleFinance(A20, ""price"", TODAY()-30, TODAY()),{""color"",""blue"";""linewidth"",2}) "),"#N/A") -> #N/A | M20: =IFERROR(__xludf.DUMMYFUNCTION("GOOGLEFINANCE(A20,""currency"")"),"#N/A") -> #N/A | N20: =round(D20/AE20-1,4) -> #N/A | O20: =IFERROR(__xludf.DUMMYFUNCTION("GOOGLEFINANCE(A20,""Change"")"),"#N/A") -> #N/A | P20: =IFERROR(__xludf.DUMMYFUNCTION("GOOGLEFINANCE(A20,""High"")"),"#N/A") -> #N/A | Q20: =IFERROR(__xludf.DUMMYFUNCTION("GOOGLEFINANCE(A20,""low"")"),"#N/A") -> #N/A | R20: =IFERROR(__xludf.DUMMYFUNCTION("abs(P20-Q20)/GOOGLEFINANCE(A20,""closeyest"")"),"#N/A") -> #N/A | S20: =D20/Y20-1 -> #N/A | W20: =IF(ISERROR(if(or(AND(Q20<=T20,T20<=P20),AND(Q20<=U20, U20<=P20)),"TRADE ALERT","")),"DATA UNAVAILABLE",if(or(AND(Q20<=T20,T20<=P20),T20>P20,AND(Q20<=U20, U20<=P20)),"TRADE ALERT"&" - Price level hit for "&A20&" currently at "&D20&" "&B20,"")) -> DATA UNAVAILABLE | X20: =IFERROR(__xludf.DUMMYFUNCTION("GOOGLEFINANCE($A20,X$3)"),"#N/A") -> #N/A | Y20: =IFERROR(__xludf.DUMMYFUNCTION("GOOGLEFINANCE($A20,Y$3)"),"#N/A") -> #N/A | Z20: =IFERROR(__xludf.DUMMYFUNCTION("GOOGLEFINANCE($A20,Z$3)"),"#N/A") -> #N/A | AA20: =IFERROR(__xludf.DUMMYFUNCTION("GOOGLEFINANCE($A20,AA$3)"),"#N/A") -> #N/A | AB20: =IFERROR(__xludf.DUMMYFUNCTION("GOOGLEFINANCE($A20,AB$3)"),"#N/A") -> #N/A | AC20: =IFERROR(__xludf.DUMMYFUNCTION("GOOGLEFINANCE($A20,AC$3)"),"#N/A") -> #N/A | AD20: =IFERROR(__xludf.DUMMYFUNCTION("GOOGLEFINANCE($A20,AD$3)"),"#N/A") -> #N/A | AE20: =IFERROR(__xludf.DUMMYFUNCTION("GOOGLEFINANCE($A20,AE$3)"),"#N/A") -> #N/A
B21: =IFERROR(__xludf.DUMMYFUNCTION("GOOGLEFINANCE(A21,""name"")"),"#N/A") -> #N/A | D21: =IFERROR(__xludf.DUMMYFUNCTION("GOOGLEFINANCE(A21)"),"#N/A") -> #N/A | F21: =IF(M21="USD",E21/1.21,E21) -> #N/A | H21: =IFERROR(__xludf.DUMMYFUNCTION("if(isblank(A21)=TRUE,0,if(M21=""GBX"",F21*G21/100,IF(M21=""EUR"",F21*G21/GOOGLEFINANCE(""CURRENCY:GBPEUR""),F21*G21/GOOGLEFINANCE(""CURRENCY:GBPUSD""))))"),0.0) -> 0 | I21: =IFERROR(__xludf.DUMMYFUNCTION("if(isblank(A21)=TRUE,0,if(M21=""GBX"",D21*G21/100,IF(M21=""EUR"",D21*G21/GOOGLEFINANCE(""CURRENCY:GBPEUR""),D21*G21/GOOGLEFINANCE(""CURRENCY:GBPUSD""))))"),0.0) -> 0 | J21: =H21/$B$1 -> 0 | K21: =I21/H21-1 -> #DIV/0! | L21: =IFERROR(__xludf.DUMMYFUNCTION("SPARKLINE(GoogleFinance(A21, ""price"", TODAY()-30, TODAY()),{""color"",""blue"";""linewidth"",2}) "),"#N/A") -> #N/A | M21: =IFERROR(__xludf.DUMMYFUNCTION("GOOGLEFINANCE(A21,""currency"")"),"#N/A") -> #N/A | N21: =round(D21/AE21-1,4) -> #N/A | O21: =IFERROR(__xludf.DUMMYFUNCTION("GOOGLEFINANCE(A21,""Change"")"),"#N/A") -> #N/A | P21: =IFERROR(__xludf.DUMMYFUNCTION("GOOGLEFINANCE(A21,""High"")"),"#N/A") -> #N/A | Q21: =IFERROR(__xludf.DUMMYFUNCTION("GOOGLEFINANCE(A21,""low"")"),"#N/A") -> #N/A | R21: =IFERROR(__xludf.DUMMYFUNCTION("abs(P21-Q21)/GOOGLEFINANCE(A21,""closeyest"")"),"#N/A") -> #N/A | S21: =D21/Y21-1 -> #N/A | W21: =IF(ISERROR(if(or(AND(Q21<=T21,T21<=P21),AND(Q21<=U21, U21<=P21)),"TRADE ALERT","")),"DATA UNAVAILABLE",if(or(AND(Q21<=T21,T21<=P21),T21>P21,AND(Q21<=U21, U21<=P21)),"TRADE ALERT"&" - Price level hit for "&A21&" currently at "&D21&" "&B21,"")) -> DATA UNAVAILABLE | X21: =IFERROR(__xludf.DUMMYFUNCTION("GOOGLEFINANCE($A21,X$3)"),"#N/A") -> #N/A | Y21: =IFERROR(__xludf.DUMMYFUNCTION("GOOGLEFINANCE($A21,Y$3)"),"#N/A") -> #N/A | Z21: =IFERROR(__xludf.DUMMYFUNCTION("GOOGLEFINANCE($A21,Z$3)"),"#N/A") -> #N/A | AA21: =IFERROR(__xludf.DUMMYFUNCTION("GOOGLEFINANCE($A21,AA$3)"),"#N/A") -> #N/A | AB21: =IFERROR(__xludf.DUMMYFUNCTION("GOOGLEFINANCE($A21,AB$3)"),"#N/A") -> #N/A | AC21: =IFERROR(__xludf.DUMMYFUNCTION("GOOGLEFINANCE($A21,AC$3)"),"#N/A") -> #N/A | AD21: =IFERROR(__xludf.DUMMYFUNCTION("GOOGLEFINANCE($A21,AD$3)"),"#N/A") -> #N/A | AE21: =IFERROR(__xludf.DUMMYFUNCTION("GOOGLEFINANCE($A21,AE$3)"),"#N/A") -> #N/A
B22: =IFERROR(__xludf.DUMMYFUNCTION("GOOGLEFINANCE(A22,""name"")"),"#N/A") -> #N/A | D22: =IFERROR(__xludf.DUMMYFUNCTION("GOOGLEFINANCE(A22)"),"#N/A") -> #N/A | F22: =IF(M22="USD",E22/1.21,E22) -> #N/A | H22: =IFERROR(__xludf.DUMMYFUNCTION("if(isblank(A22)=TRUE,0,if(M22=""GBX"",F22*G22/100,IF(M22=""EUR"",F22*G22/GOOGLEFINANCE(""CURRENCY:GBPEUR""),F22*G22/GOOGLEFINANCE(""CURRENCY:GBPUSD""))))"),0.0) -> 0 | I22: =IFERROR(__xludf.DUMMYFUNCTION("if(isblank(A22)=TRUE,0,if(M22=""GBX"",D22*G22/100,IF(M22=""EUR"",D22*G22/GOOGLEFINANCE(""CURRENCY:GBPEUR""),D22*G22/GOOGLEFINANCE(""CURRENCY:GBPUSD""))))"),0.0) -> 0 | J22: =H22/$B$1 -> 0 | K22: =I22/H22-1 -> #DIV/0! | L22: =IFERROR(__xludf.DUMMYFUNCTION("SPARKLINE(GoogleFinance(A22, ""price"", TODAY()-30, TODAY()),{""color"",""blue"";""linewidth"",2}) "),"#N/A") -> #N/A | M22: =IFERROR(__xludf.DUMMYFUNCTION("GOOGLEFINANCE(A22,""currency"")"),"#N/A") -> #N/A | N22: =round(D22/AE22-1,4) -> #N/A | O22: =IFERROR(__xludf.DUMMYFUNCTION("GOOGLEFINANCE(A22,""Change"")"),"#N/A") -> #N/A | P22: =IFERROR(__xludf.DUMMYFUNCTION("GOOGLEFINANCE(A22,""High"")"),"#N/A") -> #N/A | Q22: =IFERROR(__xludf.DUMMYFUNCTION("GOOGLEFINANCE(A22,""low"")"),"#N/A") -> #N/A | R22: =IFERROR(__xludf.DUMMYFUNCTION("abs(P22-Q22)/GOOGLEFINANCE(A22,""closeyest"")"),"#N/A") -> #N/A | S22: =D22/Y22-1 -> #N/A | W22: =IF(ISERROR(if(or(AND(Q22<=T22,T22<=P22),AND(Q22<=U22, U22<=P22)),"TRADE ALERT","")),"DATA UNAVAILABLE",if(or(AND(Q22<=T22,T22<=P22),T22>P22,AND(Q22<=U22, U22<=P22)),"TRADE ALERT"&" - Price level hit for "&A22&" currently at "&D22&" "&B22,"")) -> DATA UNAVAILABLE | X22: =IFERROR(__xludf.DUMMYFUNCTION("GOOGLEFINANCE($A22,X$3)"),"#N/A") -> #N/A | Y22: =IFERROR(__xludf.DUMMYFUNCTION("GOOGLEFINANCE($A22,Y$3)"),"#N/A") -> #N/A | Z22: =IFERROR(__xludf.DUMMYFUNCTION("GOOGLEFINANCE($A22,Z$3)"),"#N/A") -> #N/A | AA22: =IFERROR(__xludf.DUMMYFUNCTION("GOOGLEFINANCE($A22,AA$3)"),"#N/A") -> #N/A | AB22: =IFERROR(__xludf.DUMMYFUNCTION("GOOGLEFINANCE($A22,AB$3)"),"#N/A") -> #N/A | AC22: =IFERROR(__xludf.DUMMYFUNCTION("GOOGLEFINANCE($A22,AC$3)"),"#N/A") -> #N/A | AD22: =IFERROR(__xludf.DUMMYFUNCTION("GOOGLEFINANCE($A22,AD$3)"),"#N/A") -> #N/A | AE22: =IFERROR(__xludf.DUMMYFUNCTION("GOOGLEFINANCE($A22,AE$3)"),"#N/A") -> #N/A
B23: =IFERROR(__xludf.DUMMYFUNCTION("GOOGLEFINANCE(A23,""name"")"),"#N/A") -> #N/A | D23: =IFERROR(__xludf.DUMMYFUNCTION("GOOGLEFINANCE(A23)"),"#N/A") -> #N/A | F23: =IF(M23="USD",E23/1.21,E23) -> #N/A | H23: =IFERROR(__xludf.DUMMYFUNCTION("if(isblank(A23)=TRUE,0,if(M23=""GBX"",F23*G23/100,IF(M23=""EUR"",F23*G23/GOOGLEFINANCE(""CURRENCY:GBPEUR""),F23*G23/GOOGLEFINANCE(""CURRENCY:GBPUSD""))))"),0.0) -> 0 | I23: =IFERROR(__xludf.DUMMYFUNCTION("if(isblank(A23)=TRUE,0,if(M23=""GBX"",D23*G23/100,IF(M23=""EUR"",D23*G23/GOOGLEFINANCE(""CURRENCY:GBPEUR""),D23*G23/GOOGLEFINANCE(""CURRENCY:GBPUSD""))))"),0.0) -> 0 | J23: =H23/$B$1 -> 0 | K23: =I23/H23-1 -> #DIV/0! | L23: =IFERROR(__xludf.DUMMYFUNCTION("SPARKLINE(GoogleFinance(A23, ""price"", TODAY()-30, TODAY()),{""color"",""blue"";""linewidth"",2}) "),"#N/A") -> #N/A | M23: =IFERROR(__xludf.DUMMYFUNCTION("GOOGLEFINANCE(A23,""currency"")"),"#N/A") -> #N/A | N23: =round(D23/AE23-1,4) -> #N/A | O23: =IFERROR(__xludf.DUMMYFUNCTION("GOOGLEFINANCE(A23,""Change"")"),"#N/A") -> #N/A | P23: =IFERROR(__xludf.DUMMYFUNCTION("GOOGLEFINANCE(A23,""High"")"),"#N/A") -> #N/A | Q23: =IFERROR(__xludf.DUMMYFUNCTION("GOOGLEFINANCE(A23,""low"")"),"#N/A") -> #N/A | R23: =IFERROR(__xludf.DUMMYFUNCTION("abs(P23-Q23)/GOOGLEFINANCE(A23,""closeyest"")"),"#N/A") -> #N/A | S23: =D23/Y23-1 -> #N/A | W23: =IF(ISERROR(if(or(AND(Q23<=T23,T23<=P23),AND(Q23<=U23, U23<=P23)),"TRADE ALERT","")),"DATA UNAVAILABLE",if(or(AND(Q23<=T23,T23<=P23),T23>P23,AND(Q23<=U23, U23<=P23)),"TRADE ALERT"&" - Price level hit for "&A23&" currently at "&D23&" "&B23,"")) -> DATA UNAVAILABLE | X23: =IFERROR(__xludf.DUMMYFUNCTION("GOOGLEFINANCE($A23,X$3)"),"#N/A") -> #N/A | Y23: =IFERROR(__xludf.DUMMYFUNCTION("GOOGLEFINANCE($A23,Y$3)"),"#N/A") -> #N/A | Z23: =IFERROR(__xludf.DUMMYFUNCTION("GOOGLEFINANCE($A23,Z$3)"),"#N/A") -> #N/A | AA23: =IFERROR(__xludf.DUMMYFUNCTION("GOOGLEFINANCE($A23,AA$3)"),"#N/A") -> #N/A | AB23: =IFERROR(__xludf.DUMMYFUNCTION("GOOGLEFINANCE($A23,AB$3)"),"#N/A") -> #N/A | AC23: =IFERROR(__xludf.DUMMYFUNCTION("GOOGLEFINANCE($A23,AC$3)"),"#N/A") -> #N/A | AD23: =IFERROR(__xludf.DUMMYFUNCTION("GOOGLEFINANCE($A23,AD$3)"),"#N/A") -> #N/A | AE23: =IFERROR(__xludf.DUMMYFUNCTION("GOOGLEFINANCE($A23,AE$3)"),"#N/A") -> #N/A
B24: =IFERROR(__xludf.DUMMYFUNCTION("GOOGLEFINANCE(A24,""name"")"),"#N/A") -> #N/A | D24: =IFERROR(__xludf.DUMMYFUNCTION("GOOGLEFINANCE(A24)"),"#N/A") -> #N/A | F24: =IF(M24="USD",E24/1.21,E24) -> #N/A | H24: =IFERROR(__xludf.DUMMYFUNCTION("if(isblank(A24)=TRUE,0,if(M24=""GBX"",F24*G24/100,IF(M24=""EUR"",F24*G24/GOOGLEFINANCE(""CURRENCY:GBPEUR""),F24*G24/GOOGLEFINANCE(""CURRENCY:GBPUSD""))))"),0.0) -> 0 | I24: =IFERROR(__xludf.DUMMYFUNCTION("if(isblank(A24)=TRUE,0,if(M24=""GBX"",D24*G24/100,IF(M24=""EUR"",D24*G24/GOOGLEFINANCE(""CURRENCY:GBPEUR""),D24*G24/GOOGLEFINANCE(""CURRENCY:GBPUSD""))))"),0.0) -> 0 | J24: =H24/$B$1 -> 0 | K24: =I24/H24-1 -> #DIV/0! | L24: =IFERROR(__xludf.DUMMYFUNCTION("SPARKLINE(GoogleFinance(A24, ""price"", TODAY()-30, TODAY()),{""color"",""blue"";""linewidth"",2}) "),"#N/A") -> #N/A | M24: =IFERROR(__xludf.DUMMYFUNCTION("GOOGLEFINANCE(A24,""currency"")"),"#N/A") -> #N/A | N24: =round(D24/AE24-1,4) -> #N/A | O24: =IFERROR(__xludf.DUMMYFUNCTION("GOOGLEFINANCE(A24,""Change"")"),"#N/A") -> #N/A | P24: =IFERROR(__xludf.DUMMYFUNCTION("GOOGLEFINANCE(A24,""High"")"),"#N/A") -> #N/A | Q24: =IFERROR(__xludf.DUMMYFUNCTION("GOOGLEFINANCE(A24,""low"")"),"#N/A") -> #N/A | R24: =IFERROR(__xludf.DUMMYFUNCTION("abs(P24-Q24)/GOOGLEFINANCE(A24,""closeyest"")"),"#N/A") -> #N/A | S24: =D24/Y24-1 -> #N/A | W24: =IF(ISERROR(if(or(AND(Q24<=T24,T24<=P24),AND(Q24<=U24, U24<=P24)),"TRADE ALERT","")),"DATA UNAVAILABLE",if(or(AND(Q24<=T24,T24<=P24),T24>P24,AND(Q24<=U24, U24<=P24)),"TRADE ALERT"&" - Price level hit for "&A24&" currently at "&D24&" "&B24,"")) -> DATA UNAVAILABLE | X24: =IFERROR(__xludf.DUMMYFUNCTION("GOOGLEFINANCE($A24,X$3)"),"#N/A") -> #N/A | Y24: =IFERROR(__xludf.DUMMYFUNCTION("GOOGLEFINANCE($A24,Y$3)"),"#N/A") -> #N/A | Z24: =IFERROR(__xludf.DUMMYFUNCTION("GOOGLEFINANCE($A24,Z$3)"),"#N/A") -> #N/A | AA24: =IFERROR(__xludf.DUMMYFUNCTION("GOOGLEFINANCE($A24,AA$3)"),"#N/A") -> #N/A | AB24: =IFERROR(__xludf.DUMMYFUNCTION("GOOGLEFINANCE($A24,AB$3)"),"#N/A") -> #N/A | AC24: =IFERROR(__xludf.DUMMYFUNCTION("GOOGLEFINANCE($A24,AC$3)"),"#N/A") -> #N/A | AD24: =IFERROR(__xludf.DUMMYFUNCTION("GOOGLEFINANCE($A24,AD$3)"),"#N/A") -> #N/A | AE24: =IFERROR(__xludf.DUMMYFUNCTION("GOOGLEFINANCE($A24,AE$3)"),"#N/A") -> #N/A
B25: =IFERROR(__xludf.DUMMYFUNCTION("GOOGLEFINANCE(A25,""name"")"),"#N/A") -> #N/A | D25: =IFERROR(__xludf.DUMMYFUNCTION("GOOGLEFINANCE(A25)"),"#N/A") -> #N/A | F25: =IF(M25="USD",E25/1.21,E25) -> #N/A | H25: =IFERROR(__xludf.DUMMYFUNCTION("if(isblank(A25)=TRUE,0,if(M25=""GBX"",F25*G25/100,IF(M25=""EUR"",F25*G25/GOOGLEFINANCE(""CURRENCY:GBPEUR""),F25*G25/GOOGLEFINANCE(""CURRENCY:GBPUSD""))))"),0.0) -> 0 | I25: =IFERROR(__xludf.DUMMYFUNCTION("if(isblank(A25)=TRUE,0,if(M25=""GBX"",D25*G25/100,IF(M25=""EUR"",D25*G25/GOOGLEFINANCE(""CURRENCY:GBPEUR""),D25*G25/GOOGLEFINANCE(""CURRENCY:GBPUSD""))))"),0.0) -> 0 | J25: =H25/$B$1 -> 0 | K25: =I25/H25-1 -> #DIV/0! | L25: =IFERROR(__xludf.DUMMYFUNCTION("SPARKLINE(GoogleFinance(A25, ""price"", TODAY()-30, TODAY()),{""color"",""blue"";""linewidth"",2}) "),"#N/A") -> #N/A | M25: =IFERROR(__xludf.DUMMYFUNCTION("GOOGLEFINANCE(A25,""currency"")"),"#N/A") -> #N/A | N25: =round(D25/AE25-1,4) -> #N/A | O25: =IFERROR(__xludf.DUMMYFUNCTION("GOOGLEFINANCE(A25,""Change"")"),"#N/A") -> #N/A | P25: =IFERROR(__xludf.DUMMYFUNCTION("GOOGLEFINANCE(A25,""High"")"),"#N/A") -> #N/A | Q25: =IFERROR(__xludf.DUMMYFUNCTION("GOOGLEFINANCE(A25,""low"")"),"#N/A") -> #N/A | R25: =IFERROR(__xludf.DUMMYFUNCTION("abs(P25-Q25)/GOOGLEFINANCE(A25,""closeyest"")"),"#N/A") -> #N/A | S25: =D25/Y25-1 -> #N/A | W25: =IF(ISERROR(if(or(AND(Q25<=T25,T25<=P25),AND(Q25<=U25, U25<=P25)),"TRADE ALERT","")),"DATA UNAVAILABLE",if(or(AND(Q25<=T25,T25<=P25),T25>P25,AND(Q25<=U25, U25<=P25)),"TRADE ALERT"&" - Price level hit for "&A25&" currently at "&D25&" "&B25,"")) -> DATA UNAVAILABLE | X25: =IFERROR(__xludf.DUMMYFUNCTION("GOOGLEFINANCE($A25,X$3)"),"#N/A") -> #N/A | Y25: =IFERROR(__xludf.DUMMYFUNCTION("GOOGLEFINANCE($A25,Y$3)"),"#N/A") -> #N/A | Z25: =IFERROR(__xludf.DUMMYFUNCTION("GOOGLEFINANCE($A25,Z$3)"),"#N/A") -> #N/A | AA25: =IFERROR(__xludf.DUMMYFUNCTION("GOOGLEFINANCE($A25,AA$3)"),"#N/A") -> #N/A | AB25: =IFERROR(__xludf.DUMMYFUNCTION("GOOGLEFINANCE($A25,AB$3)"),"#N/A") -> #N/A | AC25: =IFERROR(__xludf.DUMMYFUNCTION("GOOGLEFINANCE($A25,AC$3)"),"#N/A") -> #N/A | AD25: =IFERROR(__xludf.DUMMYFUNCTION("GOOGLEFINANCE($A25,AD$3)"),"#N/A") -> #N/A | AE25: =IFERROR(__xludf.DUMMYFUNCTION("GOOGLEFINANCE($A25,AE$3)"),"#N/A") -> #N/A
B26: =IFERROR(__xludf.DUMMYFUNCTION("GOOGLEFINANCE(A26,""name"")"),"#N/A") -> #N/A | D26: =IFERROR(__xludf.DUMMYFUNCTION("GOOGLEFINANCE(A26)"),"#N/A") -> #N/A | F26: =IF(M26="USD",E26/1.21,E26) -> #N/A | H26: =IFERROR(__xludf.DUMMYFUNCTION("if(isblank(A26)=TRUE,0,if(M26=""GBX"",F26*G26/100,IF(M26=""EUR"",F26*G26/GOOGLEFINANCE(""CURRENCY:GBPEUR""),F26*G26/GOOGLEFINANCE(""CURRENCY:GBPUSD""))))"),0.0) -> 0 | I26: =IFERROR(__xludf.DUMMYFUNCTION("if(isblank(A26)=TRUE,0,if(M26=""GBX"",D26*G26/100,IF(M26=""EUR"",D26*G26/GOOGLEFINANCE(""CURRENCY:GBPEUR""),D26*G26/GOOGLEFINANCE(""CURRENCY:GBPUSD""))))"),0.0) -> 0 | J26: =H26/$B$1 -> 0 | K26: =I26/H26-1 -> #DIV/0! | L26: =IFERROR(__xludf.DUMMYFUNCTION("SPARKLINE(GoogleFinance(A26, ""price"", TODAY()-30, TODAY()),{""color"",""blue"";""linewidth"",2}) "),"#N/A") -> #N/A | M26: =IFERROR(__xludf.DUMMYFUNCTION("GOOGLEFINANCE(A26,""currency"")"),"#N/A") -> #N/A | N26: =round(D26/AE26-1,4) -> #N/A | O26: =IFERROR(__xludf.DUMMYFUNCTION("GOOGLEFINANCE(A26,""Change"")"),"#N/A") -> #N/A | P26: =IFERROR(__xludf.DUMMYFUNCTION("GOOGLEFINANCE(A26,""High"")"),"#N/A") -> #N/A | Q26: =IFERROR(__xludf.DUMMYFUNCTION("GOOGLEFINANCE(A26,""low"")"),"#N/A") -> #N/A | R26: =IFERROR(__xludf.DUMMYFUNCTION("abs(P26-Q26)/GOOGLEFINANCE(A26,""closeyest"")"),"#N/A") -> #N/A | S26: =D26/Y26-1 -> #N/A | W26: =IF(ISERROR(if(or(AND(Q26<=T26,T26<=P26),AND(Q26<=U26, U26<=P26)),"TRADE ALERT","")),"DATA UNAVAILABLE",if(or(AND(Q26<=T26,T26<=P26),T26>P26,AND(Q26<=U26, U26<=P26)),"TRADE ALERT"&" - Price level hit for "&A26&" currently at "&D26&" "&B26,"")) -> DATA UNAVAILABLE | X26: =IFERROR(__xludf.DUMMYFUNCTION("GOOGLEFINANCE($A26,X$3)"),"#N/A") -> #N/A | Y26: =IFERROR(__xludf.DUMMYFUNCTION("GOOGLEFINANCE($A26,Y$3)"),"#N/A") -> #N/A | Z26: =IFERROR(__xludf.DUMMYFUNCTION("GOOGLEFINANCE($A26,Z$3)"),"#N/A") -> #N/A | AA26: =IFERROR(__xludf.DUMMYFUNCTION("GOOGLEFINANCE($A26,AA$3)"),"#N/A") -> #N/A | AB26: =IFERROR(__xludf.DUMMYFUNCTION("GOOGLEFINANCE($A26,AB$3)"),"#N/A") -> #N/A | AC26: =IFERROR(__xludf.DUMMYFUNCTION("GOOGLEFINANCE($A26,AC$3)"),"#N/A") -> #N/A | AD26: =IFERROR(__xludf.DUMMYFUNCTION("GOOGLEFINANCE($A26,AD$3)"),"#N/A") -> #N/A | AE26: =IFERROR(__xludf.DUMMYFUNCTION("GOOGLEFINANCE($A26,AE$3)"),"#N/A") -> #N/A
B27: =IFERROR(__xludf.DUMMYFUNCTION("GOOGLEFINANCE(A27,""name"")"),"#N/A") -> #N/A | D27: =IFERROR(__xludf.DUMMYFUNCTION("GOOGLEFINANCE(A27)"),"#N/A") -> #N/A | F27: =IF(M27="USD",E27/1.21,E27) -> #N/A | H27: =IFERROR(__xludf.DUMMYFUNCTION("if(isblank(A27)=TRUE,0,if(M27=""GBX"",F27*G27/100,IF(M27=""EUR"",F27*G27/GOOGLEFINANCE(""CURRENCY:GBPEUR""),F27*G27/GOOGLEFINANCE(""CURRENCY:GBPUSD""))))"),0.0) -> 0 | I27: =IFERROR(__xludf.DUMMYFUNCTION("if(isblank(A27)=TRUE,0,if(M27=""GBX"",D27*G27/100,IF(M27=""EUR"",D27*G27/GOOGLEFINANCE(""CURRENCY:GBPEUR""),D27*G27/GOOGLEFINANCE(""CURRENCY:GBPUSD""))))"),0.0) -> 0 | J27: =H27/$B$1 -> 0 | K27: =I27/H27-1 -> #DIV/0! | L27: =IFERROR(__xludf.DUMMYFUNCTION("SPARKLINE(GoogleFinance(A27, ""price"", TODAY()-30, TODAY()),{""color"",""blue"";""linewidth"",2}) "),"#N/A") -> #N/A | M27: =IFERROR(__xludf.DUMMYFUNCTION("GOOGLEFINANCE(A27,""currency"")"),"#N/A") -> #N/A | N27: =round(D27/AE27-1,4) -> #N/A | O27: =IFERROR(__xludf.DUMMYFUNCTION("GOOGLEFINANCE(A27,""Change"")"),"#N/A") -> #N/A | P27: =IFERROR(__xludf.DUMMYFUNCTION("GOOGLEFINANCE(A27,""High"")"),"#N/A") -> #N/A | Q27: =IFERROR(__xludf.DUMMYFUNCTION("GOOGLEFINANCE(A27,""low"")"),"#N/A") -> #N/A | R27: =IFERROR(__xludf.DUMMYFUNCTION("abs(P27-Q27)/GOOGLEFINANCE(A27,""closeyest"")"),"#N/A") -> #N/A | S27: =D27/Y27-1 -> #N/A | W27: =IF(ISERROR(if(or(AND(Q27<=T27,T27<=P27),AND(Q27<=U27, U27<=P27)),"TRADE ALERT","")),"DATA UNAVAILABLE",if(or(AND(Q27<=T27,T27<=P27),T27>P27,AND(Q27<=U27, U27<=P27)),"TRADE ALERT"&" - Price level hit for "&A27&" currently at "&D27&" "&B27,"")) -> DATA UNAVAILABLE | X27: =IFERROR(__xludf.DUMMYFUNCTION("GOOGLEFINANCE($A27,X$3)"),"#N/A") -> #N/A | Y27: =IFERROR(__xludf.DUMMYFUNCTION("GOOGLEFINANCE($A27,Y$3)"),"#N/A") -> #N/A | Z27: =IFERROR(__xludf.DUMMYFUNCTION("GOOGLEFINANCE($A27,Z$3)"),"#N/A") -> #N/A | AA27: =IFERROR(__xludf.DUMMYFUNCTION("GOOGLEFINANCE($A27,AA$3)"),"#N/A") -> #N/A | AB27: =IFERROR(__xludf.DUMMYFUNCTION("GOOGLEFINANCE($A27,AB$3)"),"#N/A") -> #N/A | AC27: =IFERROR(__xludf.DUMMYFUNCTION("GOOGLEFINANCE($A27,AC$3)"),"#N/A") -> #N/A | AD27: =IFERROR(__xludf.DUMMYFUNCTION("GOOGLEFINANCE($A27,AD$3)"),"#N/A") -> #N/A | AE27: =IFERROR(__xludf.DUMMYFUNCTION("GOOGLEFINANCE($A27,AE$3)"),"#N/A") -> #N/A
B28: =IFERROR(__xludf.DUMMYFUNCTION("GOOGLEFINANCE(A28,""name"")"),"#N/A") -> #N/A | D28: =IFERROR(__xludf.DUMMYFUNCTION("GOOGLEFINANCE(A28)"),"#N/A") -> #N/A | F28: =IF(M28="USD",E28/1.21,E28) -> #N/A | H28: =IFERROR(__xludf.DUMMYFUNCTION("if(isblank(A28)=TRUE,0,if(M28=""GBX"",F28*G28/100,IF(M28=""EUR"",F28*G28/GOOGLEFINANCE(""CURRENCY:GBPEUR""),F28*G28/GOOGLEFINANCE(""CURRENCY:GBPUSD""))))"),0.0) -> 0 | I28: =IFERROR(__xludf.DUMMYFUNCTION("if(isblank(A28)=TRUE,0,if(M28=""GBX"",D28*G28/100,IF(M28=""EUR"",D28*G28/GOOGLEFINANCE(""CURRENCY:GBPEUR""),D28*G28/GOOGLEFINANCE(""CURRENCY:GBPUSD""))))"),0.0) -> 0 | J28: =H28/$B$1 -> 0 | K28: =I28/H28-1 -> #DIV/0! | L28: =IFERROR(__xludf.DUMMYFUNCTION("SPARKLINE(GoogleFinance(A28, ""price"", TODAY()-30, TODAY()),{""color"",""blue"";""linewidth"",2}) "),"#N/A") -> #N/A | M28: =IFERROR(__xludf.DUMMYFUNCTION("GOOGLEFINANCE(A28,""currency"")"),"#N/A") -> #N/A | N28: =round(D28/AE28-1,4) -> #N/A | O28: =IFERROR(__xludf.DUMMYFUNCTION("GOOGLEFINANCE(A28,""Change"")"),"#N/A") -> #N/A | P28: =IFERROR(__xludf.DUMMYFUNCTION("GOOGLEFINANCE(A28,""High"")"),"#N/A") -> #N/A | Q28: =IFERROR(__xludf.DUMMYFUNCTION("GOOGLEFINANCE(A28,""low"")"),"#N/A") -> #N/A | R28: =IFERROR(__xludf.DUMMYFUNCTION("abs(P28-Q28)/GOOGLEFINANCE(A28,""closeyest"")"),"#N/A") -> #N/A | S28: =D28/Y28-1 -> #N/A | W28: =IF(ISERROR(if(or(AND(Q28<=T28,T28<=P28),AND(Q28<=U28, U28<=P28)),"TRADE ALERT","")),"DATA UNAVAILABLE",if(or(AND(Q28<=T28,T28<=P28),T28>P28,AND(Q28<=U28, U28<=P28)),"TRADE ALERT"&" - Price level hit for "&A28&" currently at "&D28&" "&B28,"")) -> DATA UNAVAILABLE | X28: =IFERROR(__xludf.DUMMYFUNCTION("GOOGLEFINANCE($A28,X$3)"),"#N/A") -> #N/A | Y28: =IFERROR(__xludf.DUMMYFUNCTION("GOOGLEFINANCE($A28,Y$3)"),"#N/A") -> #N/A | Z28: =IFERROR(__xludf.DUMMYFUNCTION("GOOGLEFINANCE($A28,Z$3)"),"#N/A") -> #N/A | AA28: =IFERROR(__xludf.DUMMYFUNCTION("GOOGLEFINANCE($A28,AA$3)"),"#N/A") -> #N/A | AB28: =IFERROR(__xludf.DUMMYFUNCTION("GOOGLEFINANCE($A28,AB$3)"),"#N/A") -> #N/A | AC28: =IFERROR(__xludf.DUMMYFUNCTION("GOOGLEFINANCE($A28,AC$3)"),"#N/A") -> #N/A | AD28: =IFERROR(__xludf.DUMMYFUNCTION("GOOGLEFINANCE($A28,AD$3)"),"#N/A") -> #N/A | AE28: =IFERROR(__xludf.DUMMYFUNCTION("GOOGLEFINANCE($A28,AE$3)"),"#N/A") -> #N/A
A29: Watchlist Favourites | C29: Watch Reason
A30: ='Virtual Portfolio'!A33 -> SNAP | B30: =IFERROR(__xludf.DUMMYFUNCTION("GOOGLEFINANCE(A30,""name"")"),"Snap Inc") -> Snap Inc | C30: ='Virtual Portfolio'!C33 | D30: =IFERROR(__xludf.DUMMYFUNCTION("GOOGLEFINANCE(A30)"),4.75) -> 4.75 | K30: =(D30-E30)/E30 -> #DIV/0! | L30: =IFERROR(__xludf.DUMMYFUNCTION("SPARKLINE(GoogleFinance(A30, ""price"", TODAY()-30, TODAY()),{""color"",""blue"";""linewidth"",2}) "),"") | M30: =IFERROR(__xludf.DUMMYFUNCTION("GOOGLEFINANCE(A30,""currency"")"),"USD") -> USD | N30: =round(D30/AE30-1,4) -> -0.0166 | O30: =IFERROR(__xludf.DUMMYFUNCTION("GOOGLEFINANCE(A30,""Change"")"),-0.09) -> -0.09 | P30: =IFERROR(__xludf.DUMMYFUNCTION("GOOGLEFINANCE(A30,""High"")"),4.87) -> 4.87 | Q30: =IFERROR(__xludf.DUMMYFUNCTION("GOOGLEFINANCE(A30,""low"")"),4.66) -> 4.66 | R30: =IFERROR(__xludf.DUMMYFUNCTION("abs(P30-Q30)/GOOGLEFINANCE(A30,""closeyest"")"),0.04347826086956521) -> 0.043478261 | S30: =D30/Y30-1 -> 0.019313305 | T30: ='Virtual Portfolio'!T33 -> 15 | U30: ='Virtual Portfolio'!U33 -> 50 | W30: =IF(ISERROR(if(or(AND(Q30<=T30,T30<=P30),AND(Q30<=U30, U30<=P30)),"TRADE ALERT","")),"DATA UNAVAILABLE",if(or(AND(Q30<=T30,T30<=P30),T30>P30,AND(Q30<=U30, U30<=P30)),"TRADE ALERT"&" - Price level hit for "&A30&" currently at "&D30&" "&B30,"")) -> TRADE ALERT - Price level hit for SNAP currently at 4.75 Snap Inc | X30: =IFERROR(__xludf.DUMMYFUNCTION("GOOGLEFINANCE($A30,X$3)"),0.83) -> 0.83 | Y30: =IFERROR(__xludf.DUMMYFUNCTION("GOOGLEFINANCE($A30,Y$3)"),4.66) -> 4.66 | Z30: =IFERROR(__xludf.DUMMYFUNCTION("GOOGLEFINANCE($A30,Z$3)"),11.05) -> 11.05 | AA30: =IFERROR(__xludf.DUMMYFUNCTION("GOOGLEFINANCE($A30,AA$3)"),"#N/A") -> #N/A | AB30: =IFERROR(__xludf.DUMMYFUNCTION("GOOGLEFINANCE($A30,AB$3)"),"#N/A") -> #N/A | AC30: =IFERROR(__xludf.DUMMYFUNCTION("GOOGLEFINANCE($A30,AC$3)"),0.0) -> 0 | AD30: =IFERROR(__xludf.DUMMYFUNCTION("GOOGLEFINANCE($A30,AD$3)"),8.014072301E9) -> 8014072301 | AE30: =IFERROR(__xludf.DUMMYFUNCTION("GOOGLEFINANCE($A30,AE$3)"),4.83) -> 4.83
